Scraping bitcoin Data
Starting Year: 2015 Ending Year: 2018
Current Starting Date:2015-01-01 Current Ending Date:2015-02-01
31
Querying bitcoin OR BTC since:2015-01-01 until:2015-01-02
Querying bitcoin OR BTC since:2015-01-02 until:2015-01-03
Querying bitcoin OR BTC since:2015-01-03 until:2015-01-04
Querying bitcoin OR BTC since:2015-01-04 until:2015-01-05
Querying bitcoin OR BTC since:2015-01-05 until:2015-01-06
Querying bitcoin OR BTC since:2015-01-06 until:2015-01-07
Querying bitcoin OR BTC since:2015-01-07 until:2015-01-08
Querying bitcoin OR BTC since:2015-01-08 until:2015-01-09
Querying bitcoin OR BTC since:2015-01-09 until:2015-01-10
Querying bitcoin OR BTC since:2015-01-11 until:2015-01-12
Querying bitcoin OR BTC since:2015-01-12 until:2015-01-13
Querying bitcoin OR BTC since:2015-01-10 until:2015-01-11
Querying bitcoin OR BTC since:2015-01-14 until:2015-01-15
Querying bitcoin OR BTC since:2015-01-15 until:2015-01-16
Querying bitcoin OR BTC since:2015-01-16 until:2015-01-17
Querying bitcoin OR BTC since:2015-01-17 until:2015-01-18
Querying bitcoin OR BTC since:2015-01-21 until:2015-01-22
Querying bitcoin OR BTC since:2015-01-13 until:2015-01-14
Querying bitcoin OR BTC since:2015-01-19 until:2015-01-20
Querying bitcoin OR BTC since:2015-01-20 until:2015-01-21
Querying bitcoin OR BTC since:2015-01-18 until:2015-01-19
Querying bitcoin OR BTC since:2015-01-22 until:2015-01-23
Querying bitcoin OR BTC since:2015-01-24 until:2015-01-25
Querying bitcoin OR BTC since:2015-01-23 until:2015-01-24
Querying bitcoin OR BTC since:2015-01-25 until:2015-01-26
Querying bitcoin OR BTC since:2015-01-26 until:2015-01-27
Querying bitcoin OR BTC since:2015-01-28 until:2015-01-29
Querying bitcoin OR BTC since:2015-01-29 until:2015-01-30
Querying bitcoin OR BTC since:2015-01-30 until:2015-01-31
Querying bitcoin OR BTC since:2015-01-27 until:2015-01-28
Querying bitcoin OR BTC since:2015-01-31 until:2015-02-01
Failed to parse JSON "Expecting value: line 1 column 1 (char 0)" while requesting "https://twitter.com/i/search/timeline?vertical=default&include_available_features=1&include_entities=1&reset_error_state=false&src=typd&max_position=TWEET-553930004338573313-554032856196870144-BD1UO2FFu9QAAAAAAAAVfAAAAAcAAABWAAAAAAAAAAAAAAAAAAAAAAAAAAAAAAAAAAAAAAAAAAAAAAAAAAAAAAAAAAAAAAAAAAAAAAAAAAAAAAAAAAAAAAAAAAAAAAAAAAAAAAAAAAAAAAAAAAAAAAAAAAAAAAAAAAAAAAAAAAAAAAAAAAAAAAAAAAAAAAAAAAAAAAAAAAAAAAAAAAAAAAAAAAAAAAAAAAAAAAAAAAAAAAAAAAAAAAAAAAAAAAAAAAAAAAAAAAAAAAAAAAAAAAAAAAAAAAAAAAAAAAAAAAAAAAAAAAAAAAAAAAAAAAAAAAAAAAAAAAAAAAAAAAAAAAAAAAAAAAAAAAAAAAAAAAAAAAAAAAAAAAAAAAAAAAAAAAAAAAAAAAAAAAAAAAAAAAAAAAAAAAAAAAAAAAAAAAAAAAAAAAAAAAAAAAAAAAAAAAAAAAAAAAAAAAAAAAAAAAAAAAAAAAAAAAAAAAAAAAAAAAAAAAAAAAAAAAAAAAAAAAAAAAAAAAAAAAAAAAAAAAAAAAAAAAAAAAAAAAAAAAAAAAAAAAAAAAAAAAAAAAAAAAAAAAAAAAAAAAAAAAAAAAAAAAAAAAAAAAAAAAAAAAAAAAAAAAAAAAAAAAAAAAAAAAAAAAAAAAAAAAAAAAAAAAAAAAAAAAAAAAAAAAAAAAAAAAAAAAAAAAAAAAAAAAAAAAAAAAAAAAAAAAAAAAAAAAAAAAAAAAAAAAAAAAAAAAAAAAAAAAAAAAAAAAAAAAAAAAAAAAAAAAAAAAAAAAAAAAAAAAAAAAAAAAAAAAAAAAAAAAAAAAAAAAAAAAAAAAAAAAAAAAAAAAAAAAAAAAAAAAAAAAAAAAAAAAAAAAAAAAAAAAAAAAAAAAAAAAAAAAAAAAAAAAAAAAAAAAAAAAAAAAAAAAAAAAAAAAAAAAAAAAAAAAAAAAAAAA==-T-0-1&q=bitcoin%20OR%20BTC%20since%3A2015-01-10%20until%3A2015-01-11&l=".
Traceback (most recent call last):
  File "/home/warproxxx/Desktop/Projects/CryptoTrader/src/data_utils/twitter_data/twitterscraper/query.py", line 96, in query_single_page
    json_resp = json.loads(response.text)
  File "/usr/lib/python3.7/json/__init__.py", line 348, in loads
    return _default_decoder.decode(s)
  File "/usr/lib/python3.7/json/decoder.py", line 337, in decode
    obj, end = self.raw_decode(s, idx=_w(s, 0).end())
  File "/usr/lib/python3.7/json/decoder.py", line 355, in raw_decode
    raise JSONDecodeError("Expecting value", s, err.value) from None
json.decoder.JSONDecodeError: Expecting value: line 1 column 1 (char 0)
Retrying... (Attempts left: 10)
An unknown error occurred! Returning tweets gathered so far.
Traceback (most recent call last):
  File "/home/warproxxx/Desktop/Projects/CryptoTrader/src/data_utils/twitter_data/twitterscraper/query.py", line 158, in query_tweets_once
    pos is None
  File "/home/warproxxx/Desktop/Projects/CryptoTrader/src/data_utils/twitter_data/twitterscraper/query.py", line 89, in query_single_page
    response = requests.get(url, headers=headers)
  File "/usr/local/lib/python3.7/dist-packages/requests/api.py", line 72, in get
    return request('get', url, params=params, **kwargs)
  File "/usr/local/lib/python3.7/dist-packages/requests/api.py", line 58, in request
    return session.request(method=method, url=url, **kwargs)
  File "/usr/local/lib/python3.7/dist-packages/requests/sessions.py", line 512, in request
    resp = self.send(prep, **send_kwargs)
  File "/usr/local/lib/python3.7/dist-packages/requests/sessions.py", line 622, in send
    r = adapter.send(request, **kwargs)
  File "/usr/local/lib/python3.7/dist-packages/requests/adapters.py", line 445, in send
    timeout=timeout
  File "/usr/local/lib/python3.7/dist-packages/urllib3/connectionpool.py", line 600, in urlopen
    chunked=chunked)
  File "/usr/local/lib/python3.7/dist-packages/urllib3/connectionpool.py", line 343, in _make_request
    self._validate_conn(conn)
  File "/usr/local/lib/python3.7/dist-packages/urllib3/connectionpool.py", line 849, in _validate_conn
    conn.connect()
  File "/usr/local/lib/python3.7/dist-packages/urllib3/connection.py", line 356, in connect
    ssl_context=context)
  File "/usr/local/lib/python3.7/dist-packages/urllib3/util/ssl_.py", line 359, in ssl_wrap_socket
    return context.wrap_socket(sock, server_hostname=server_hostname)
  File "/usr/lib/python3.7/ssl.py", line 412, in wrap_socket
    session=session
  File "/usr/lib/python3.7/ssl.py", line 850, in _create
    self.do_handshake()
  File "/usr/lib/python3.7/ssl.py", line 1108, in do_handshake
    self._sslobj.do_handshake()
KeyboardInterrupt
An unknown error occurred! Returning tweets gathered so far.
Traceback (most recent call last):
  File "/usr/local/lib/python3.7/dist-packages/urllib3/connectionpool.py", line 377, in _make_request
    httplib_response = conn.getresponse(buffering=True)
TypeError: getresponse() got an unexpected keyword argument 'buffering'

During handling of the above exception, another exception occurred:

Traceback (most recent call last):
  File "/home/warproxxx/Desktop/Projects/CryptoTrader/src/data_utils/twitter_data/twitterscraper/query.py", line 158, in query_tweets_once
    pos is None
  File "/home/warproxxx/Desktop/Projects/CryptoTrader/src/data_utils/twitter_data/twitterscraper/query.py", line 89, in query_single_page
    response = requests.get(url, headers=headers)
  File "/usr/local/lib/python3.7/dist-packages/requests/api.py", line 72, in get
    return request('get', url, params=params, **kwargs)
  File "/usr/local/lib/python3.7/dist-packages/requests/api.py", line 58, in request
    return session.request(method=method, url=url, **kwargs)
  File "/usr/local/lib/python3.7/dist-packages/requests/sessions.py", line 512, in request
    resp = self.send(prep, **send_kwargs)
  File "/usr/local/lib/python3.7/dist-packages/requests/sessions.py", line 622, in send
    r = adapter.send(request, **kwargs)
  File "/usr/local/lib/python3.7/dist-packages/requests/adapters.py", line 445, in send
    timeout=timeout
  File "/usr/local/lib/python3.7/dist-packages/urllib3/connectionpool.py", line 600, in urlopen
    chunked=chunked)
  File "/usr/local/lib/python3.7/dist-packages/urllib3/connectionpool.py", line 380, in _make_request
    httplib_response = conn.getresponse()
  File "/usr/lib/python3.7/http/client.py", line 1321, in getresponse
    response.begin()
  File "/usr/lib/python3.7/http/client.py", line 296, in begin
    version, status, reason = self._read_status()
  File "/usr/lib/python3.7/http/client.py", line 257, in _read_status
    line = str(self.fp.readline(_MAXLINE + 1), "iso-8859-1")
  File "/usr/lib/python3.7/socket.py", line 589, in readinto
    return self._sock.recv_into(b)
  File "/usr/lib/python3.7/ssl.py", line 1049, in recv_into
    return self.read(nbytes, buffer)
  File "/usr/lib/python3.7/ssl.py", line 908, in read
    return self._sslobj.read(len, buffer)
KeyboardInterrupt
Got 59 tweets for bitcoin%20OR%20BTC%20since%3A2015-01-21%20until%3A2015-01-22.
Got 21 tweets for bitcoin%20OR%20BTC%20since%3A2015-01-24%20until%3A2015-01-25.
An unknown error occurred! Returning tweets gathered so far.
Traceback (most recent call last):
  File "/home/warproxxx/Desktop/Projects/CryptoTrader/src/data_utils/twitter_data/twitterscraper/query.py", line 158, in query_tweets_once
    pos is None
  File "/home/warproxxx/Desktop/Projects/CryptoTrader/src/data_utils/twitter_data/twitterscraper/query.py", line 89, in query_single_page
    response = requests.get(url, headers=headers)
  File "/usr/local/lib/python3.7/dist-packages/requests/api.py", line 72, in get
    return request('get', url, params=params, **kwargs)
  File "/usr/local/lib/python3.7/dist-packages/requests/api.py", line 58, in request
    return session.request(method=method, url=url, **kwargs)
  File "/usr/local/lib/python3.7/dist-packages/requests/sessions.py", line 512, in request
    resp = self.send(prep, **send_kwargs)
  File "/usr/local/lib/python3.7/dist-packages/requests/sessions.py", line 622, in send
    r = adapter.send(request, **kwargs)
  File "/usr/local/lib/python3.7/dist-packages/requests/adapters.py", line 445, in send
    timeout=timeout
  File "/usr/local/lib/python3.7/dist-packages/urllib3/connectionpool.py", line 600, in urlopen
    chunked=chunked)
  File "/usr/local/lib/python3.7/dist-packages/urllib3/connectionpool.py", line 343, in _make_request
    self._validate_conn(conn)
  File "/usr/local/lib/python3.7/dist-packages/urllib3/connectionpool.py", line 849, in _validate_conn
    conn.connect()
  File "/usr/local/lib/python3.7/dist-packages/urllib3/connection.py", line 314, in connect
    conn = self._new_conn()
  File "/usr/local/lib/python3.7/dist-packages/urllib3/connection.py", line 171, in _new_conn
    (self._dns_host, self.port), self.timeout, **extra_kw)
  File "/usr/local/lib/python3.7/dist-packages/urllib3/util/connection.py", line 69, in create_connection
    sock.connect(sa)
KeyboardInterrupt
Got 77 tweets for bitcoin%20OR%20BTC%20since%3A2015-01-02%20until%3A2015-01-03.
An unknown error occurred! Returning tweets gathered so far.
Traceback (most recent call last):
  File "/home/warproxxx/Desktop/Projects/CryptoTrader/src/data_utils/twitter_data/twitterscraper/query.py", line 158, in query_tweets_once
    pos is None
  File "/home/warproxxx/Desktop/Projects/CryptoTrader/src/data_utils/twitter_data/twitterscraper/query.py", line 89, in query_single_page
    response = requests.get(url, headers=headers)
  File "/usr/local/lib/python3.7/dist-packages/requests/api.py", line 72, in get
    return request('get', url, params=params, **kwargs)
  File "/usr/local/lib/python3.7/dist-packages/requests/api.py", line 58, in request
    return session.request(method=method, url=url, **kwargs)
  File "/usr/local/lib/python3.7/dist-packages/requests/sessions.py", line 512, in request
    resp = self.send(prep, **send_kwargs)
  File "/usr/local/lib/python3.7/dist-packages/requests/sessions.py", line 622, in send
    r = adapter.send(request, **kwargs)
  File "/usr/local/lib/python3.7/dist-packages/requests/adapters.py", line 445, in send
    timeout=timeout
  File "/usr/local/lib/python3.7/dist-packages/urllib3/connectionpool.py", line 600, in urlopen
    chunked=chunked)
  File "/usr/local/lib/python3.7/dist-packages/urllib3/connectionpool.py", line 343, in _make_request
    self._validate_conn(conn)
  File "/usr/local/lib/python3.7/dist-packages/urllib3/connectionpool.py", line 849, in _validate_conn
    conn.connect()
  File "/usr/local/lib/python3.7/dist-packages/urllib3/connection.py", line 314, in connect
    conn = self._new_conn()
  File "/usr/local/lib/python3.7/dist-packages/urllib3/connection.py", line 171, in _new_conn
    (self._dns_host, self.port), self.timeout, **extra_kw)
  File "/usr/local/lib/python3.7/dist-packages/urllib3/util/connection.py", line 69, in create_connection
    sock.connect(sa)
KeyboardInterrupt
An unknown error occurred! Returning tweets gathered so far.
Traceback (most recent call last):
  File "/usr/local/lib/python3.7/dist-packages/urllib3/connectionpool.py", line 377, in _make_request
    httplib_response = conn.getresponse(buffering=True)
TypeError: getresponse() got an unexpected keyword argument 'buffering'

During handling of the above exception, another exception occurred:

Traceback (most recent call last):
  File "/home/warproxxx/Desktop/Projects/CryptoTrader/src/data_utils/twitter_data/twitterscraper/query.py", line 158, in query_tweets_once
    pos is None
  File "/home/warproxxx/Desktop/Projects/CryptoTrader/src/data_utils/twitter_data/twitterscraper/query.py", line 89, in query_single_page
    response = requests.get(url, headers=headers)
  File "/usr/local/lib/python3.7/dist-packages/requests/api.py", line 72, in get
    return request('get', url, params=params, **kwargs)
  File "/usr/local/lib/python3.7/dist-packages/requests/api.py", line 58, in request
    return session.request(method=method, url=url, **kwargs)
  File "/usr/local/lib/python3.7/dist-packages/requests/sessions.py", line 512, in request
    resp = self.send(prep, **send_kwargs)
  File "/usr/local/lib/python3.7/dist-packages/requests/sessions.py", line 622, in send
    r = adapter.send(request, **kwargs)
  File "/usr/local/lib/python3.7/dist-packages/requests/adapters.py", line 445, in send
    timeout=timeout
  File "/usr/local/lib/python3.7/dist-packages/urllib3/connectionpool.py", line 600, in urlopen
    chunked=chunked)
  File "/usr/local/lib/python3.7/dist-packages/urllib3/connectionpool.py", line 380, in _make_request
    httplib_response = conn.getresponse()
  File "/usr/lib/python3.7/http/client.py", line 1321, in getresponse
    response.begin()
  File "/usr/lib/python3.7/http/client.py", line 296, in begin
    version, status, reason = self._read_status()
  File "/usr/lib/python3.7/http/client.py", line 257, in _read_status
    line = str(self.fp.readline(_MAXLINE + 1), "iso-8859-1")
  File "/usr/lib/python3.7/socket.py", line 589, in readinto
    return self._sock.recv_into(b)
  File "/usr/lib/python3.7/ssl.py", line 1049, in recv_into
    return self.read(nbytes, buffer)
  File "/usr/lib/python3.7/ssl.py", line 908, in read
    return self._sslobj.read(len, buffer)
KeyboardInterrupt
Got 20 tweets for bitcoin%20OR%20BTC%20since%3A2015-01-16%20until%3A2015-01-17.
An unknown error occurred! Returning tweets gathered so far.
Traceback (most recent call last):
  File "/home/warproxxx/Desktop/Projects/CryptoTrader/src/data_utils/twitter_data/twitterscraper/query.py", line 158, in query_tweets_once
    pos is None
  File "/home/warproxxx/Desktop/Projects/CryptoTrader/src/data_utils/twitter_data/twitterscraper/query.py", line 89, in query_single_page
    response = requests.get(url, headers=headers)
  File "/usr/local/lib/python3.7/dist-packages/requests/api.py", line 72, in get
    return request('get', url, params=params, **kwargs)
  File "/usr/local/lib/python3.7/dist-packages/requests/api.py", line 58, in request
    return session.request(method=method, url=url, **kwargs)
  File "/usr/local/lib/python3.7/dist-packages/requests/sessions.py", line 512, in request
    resp = self.send(prep, **send_kwargs)
  File "/usr/local/lib/python3.7/dist-packages/requests/sessions.py", line 622, in send
    r = adapter.send(request, **kwargs)
  File "/usr/local/lib/python3.7/dist-packages/requests/adapters.py", line 445, in send
    timeout=timeout
  File "/usr/local/lib/python3.7/dist-packages/urllib3/connectionpool.py", line 600, in urlopen
    chunked=chunked)
  File "/usr/local/lib/python3.7/dist-packages/urllib3/connectionpool.py", line 343, in _make_request
    self._validate_conn(conn)
  File "/usr/local/lib/python3.7/dist-packages/urllib3/connectionpool.py", line 849, in _validate_conn
    conn.connect()
  File "/usr/local/lib/python3.7/dist-packages/urllib3/connection.py", line 356, in connect
    ssl_context=context)
  File "/usr/local/lib/python3.7/dist-packages/urllib3/util/ssl_.py", line 359, in ssl_wrap_socket
    return context.wrap_socket(sock, server_hostname=server_hostname)
  File "/usr/lib/python3.7/ssl.py", line 412, in wrap_socket
    session=session
  File "/usr/lib/python3.7/ssl.py", line 850, in _create
    self.do_handshake()
  File "/usr/lib/python3.7/ssl.py", line 1108, in do_handshake
    self._sslobj.do_handshake()
KeyboardInterrupt
Got 60 tweets for bitcoin%20OR%20BTC%20since%3A2015-01-09%20until%3A2015-01-10.
An unknown error occurred! Returning tweets gathered so far.
Traceback (most recent call last):
  File "/home/warproxxx/Desktop/Projects/CryptoTrader/src/data_utils/twitter_data/twitterscraper/query.py", line 158, in query_tweets_once
    pos is None
  File "/home/warproxxx/Desktop/Projects/CryptoTrader/src/data_utils/twitter_data/twitterscraper/query.py", line 89, in query_single_page
    response = requests.get(url, headers=headers)
  File "/usr/local/lib/python3.7/dist-packages/requests/api.py", line 72, in get
    return request('get', url, params=params, **kwargs)
  File "/usr/local/lib/python3.7/dist-packages/requests/api.py", line 58, in request
    return session.request(method=method, url=url, **kwargs)
  File "/usr/local/lib/python3.7/dist-packages/requests/sessions.py", line 512, in request
    resp = self.send(prep, **send_kwargs)
  File "/usr/local/lib/python3.7/dist-packages/requests/sessions.py", line 622, in send
    r = adapter.send(request, **kwargs)
  File "/usr/local/lib/python3.7/dist-packages/requests/adapters.py", line 445, in send
    timeout=timeout
  File "/usr/local/lib/python3.7/dist-packages/urllib3/connectionpool.py", line 600, in urlopen
    chunked=chunked)
  File "/usr/local/lib/python3.7/dist-packages/urllib3/connectionpool.py", line 343, in _make_request
    self._validate_conn(conn)
  File "/usr/local/lib/python3.7/dist-packages/urllib3/connectionpool.py", line 849, in _validate_conn
    conn.connect()
  File "/usr/local/lib/python3.7/dist-packages/urllib3/connection.py", line 356, in connect
    ssl_context=context)
  File "/usr/local/lib/python3.7/dist-packages/urllib3/util/ssl_.py", line 359, in ssl_wrap_socket
    return context.wrap_socket(sock, server_hostname=server_hostname)
  File "/usr/lib/python3.7/ssl.py", line 412, in wrap_socket
    session=session
  File "/usr/lib/python3.7/ssl.py", line 850, in _create
    self.do_handshake()
  File "/usr/lib/python3.7/ssl.py", line 1108, in do_handshake
    self._sslobj.do_handshake()
KeyboardInterrupt
An unknown error occurred! Returning tweets gathered so far.
Traceback (most recent call last):
  File "/usr/local/lib/python3.7/dist-packages/urllib3/connectionpool.py", line 377, in _make_request
    httplib_response = conn.getresponse(buffering=True)
TypeError: getresponse() got an unexpected keyword argument 'buffering'

During handling of the above exception, another exception occurred:

Traceback (most recent call last):
  File "/home/warproxxx/Desktop/Projects/CryptoTrader/src/data_utils/twitter_data/twitterscraper/query.py", line 158, in query_tweets_once
    pos is None
  File "/home/warproxxx/Desktop/Projects/CryptoTrader/src/data_utils/twitter_data/twitterscraper/query.py", line 89, in query_single_page
    response = requests.get(url, headers=headers)
  File "/usr/local/lib/python3.7/dist-packages/requests/api.py", line 72, in get
    return request('get', url, params=params, **kwargs)
  File "/usr/local/lib/python3.7/dist-packages/requests/api.py", line 58, in request
    return session.request(method=method, url=url, **kwargs)
  File "/usr/local/lib/python3.7/dist-packages/requests/sessions.py", line 512, in request
    resp = self.send(prep, **send_kwargs)
  File "/usr/local/lib/python3.7/dist-packages/requests/sessions.py", line 622, in send
    r = adapter.send(request, **kwargs)
  File "/usr/local/lib/python3.7/dist-packages/requests/adapters.py", line 445, in send
    timeout=timeout
  File "/usr/local/lib/python3.7/dist-packages/urllib3/connectionpool.py", line 600, in urlopen
    chunked=chunked)
  File "/usr/local/lib/python3.7/dist-packages/urllib3/connectionpool.py", line 380, in _make_request
    httplib_response = conn.getresponse()
  File "/usr/lib/python3.7/http/client.py", line 1321, in getresponse
    response.begin()
  File "/usr/lib/python3.7/http/client.py", line 296, in begin
    version, status, reason = self._read_status()
  File "/usr/lib/python3.7/http/client.py", line 257, in _read_status
    line = str(self.fp.readline(_MAXLINE + 1), "iso-8859-1")
  File "/usr/lib/python3.7/socket.py", line 589, in readinto
    return self._sock.recv_into(b)
  File "/usr/lib/python3.7/ssl.py", line 1049, in recv_into
    return self.read(nbytes, buffer)
  File "/usr/lib/python3.7/ssl.py", line 908, in read
    return self._sslobj.read(len, buffer)
KeyboardInterrupt
Got 21 tweets for bitcoin%20OR%20BTC%20since%3A2015-01-25%20until%3A2015-01-26.
An unknown error occurred! Returning tweets gathered so far.
Traceback (most recent call last):
  File "/usr/local/lib/python3.7/dist-packages/urllib3/connectionpool.py", line 377, in _make_request
    httplib_response = conn.getresponse(buffering=True)
TypeError: getresponse() got an unexpected keyword argument 'buffering'

During handling of the above exception, another exception occurred:

Traceback (most recent call last):
  File "/home/warproxxx/Desktop/Projects/CryptoTrader/src/data_utils/twitter_data/twitterscraper/query.py", line 158, in query_tweets_once
    pos is None
  File "/home/warproxxx/Desktop/Projects/CryptoTrader/src/data_utils/twitter_data/twitterscraper/query.py", line 89, in query_single_page
    response = requests.get(url, headers=headers)
  File "/usr/local/lib/python3.7/dist-packages/requests/api.py", line 72, in get
    return request('get', url, params=params, **kwargs)
  File "/usr/local/lib/python3.7/dist-packages/requests/api.py", line 58, in request
    return session.request(method=method, url=url, **kwargs)
  File "/usr/local/lib/python3.7/dist-packages/requests/sessions.py", line 512, in request
    resp = self.send(prep, **send_kwargs)
  File "/usr/local/lib/python3.7/dist-packages/requests/sessions.py", line 622, in send
    r = adapter.send(request, **kwargs)
  File "/usr/local/lib/python3.7/dist-packages/requests/adapters.py", line 445, in send
    timeout=timeout
  File "/usr/local/lib/python3.7/dist-packages/urllib3/connectionpool.py", line 600, in urlopen
    chunked=chunked)
  File "/usr/local/lib/python3.7/dist-packages/urllib3/connectionpool.py", line 380, in _make_request
    httplib_response = conn.getresponse()
  File "/usr/lib/python3.7/http/client.py", line 1321, in getresponse
    response.begin()
  File "/usr/lib/python3.7/http/client.py", line 296, in begin
    version, status, reason = self._read_status()
  File "/usr/lib/python3.7/http/client.py", line 257, in _read_status
    line = str(self.fp.readline(_MAXLINE + 1), "iso-8859-1")
  File "/usr/lib/python3.7/socket.py", line 589, in readinto
    return self._sock.recv_into(b)
  File "/usr/lib/python3.7/ssl.py", line 1049, in recv_into
    return self.read(nbytes, buffer)
  File "/usr/lib/python3.7/ssl.py", line 908, in read
    return self._sslobj.read(len, buffer)
KeyboardInterrupt
Got 60 tweets for bitcoin%20OR%20BTC%20since%3A2015-01-20%20until%3A2015-01-21.
Got 61 tweets for bitcoin%20OR%20BTC%20since%3A2015-01-11%20until%3A2015-01-12.
An unknown error occurred! Returning tweets gathered so far.
Traceback (most recent call last):
  File "/home/warproxxx/Desktop/Projects/CryptoTrader/src/data_utils/twitter_data/twitterscraper/query.py", line 158, in query_tweets_once
    pos is None
  File "/home/warproxxx/Desktop/Projects/CryptoTrader/src/data_utils/twitter_data/twitterscraper/query.py", line 89, in query_single_page
    response = requests.get(url, headers=headers)
  File "/usr/local/lib/python3.7/dist-packages/requests/api.py", line 72, in get
    return request('get', url, params=params, **kwargs)
  File "/usr/local/lib/python3.7/dist-packages/requests/api.py", line 58, in request
    return session.request(method=method, url=url, **kwargs)
  File "/usr/local/lib/python3.7/dist-packages/requests/sessions.py", line 512, in request
    resp = self.send(prep, **send_kwargs)
  File "/usr/local/lib/python3.7/dist-packages/requests/sessions.py", line 622, in send
    r = adapter.send(request, **kwargs)
  File "/usr/local/lib/python3.7/dist-packages/requests/adapters.py", line 445, in send
    timeout=timeout
  File "/usr/local/lib/python3.7/dist-packages/urllib3/connectionpool.py", line 600, in urlopen
    chunked=chunked)
  File "/usr/local/lib/python3.7/dist-packages/urllib3/connectionpool.py", line 343, in _make_request
    self._validate_conn(conn)
  File "/usr/local/lib/python3.7/dist-packages/urllib3/connectionpool.py", line 849, in _validate_conn
    conn.connect()
  File "/usr/local/lib/python3.7/dist-packages/urllib3/connection.py", line 356, in connect
    ssl_context=context)
  File "/usr/local/lib/python3.7/dist-packages/urllib3/util/ssl_.py", line 359, in ssl_wrap_socket
    return context.wrap_socket(sock, server_hostname=server_hostname)
  File "/usr/lib/python3.7/ssl.py", line 412, in wrap_socket
    session=session
  File "/usr/lib/python3.7/ssl.py", line 850, in _create
    self.do_handshake()
  File "/usr/lib/python3.7/ssl.py", line 1108, in do_handshake
    self._sslobj.do_handshake()
KeyboardInterrupt
An unknown error occurred! Returning tweets gathered so far.
Traceback (most recent call last):
  File "/home/warproxxx/Desktop/Projects/CryptoTrader/src/data_utils/twitter_data/twitterscraper/query.py", line 158, in query_tweets_once
    pos is None
  File "/home/warproxxx/Desktop/Projects/CryptoTrader/src/data_utils/twitter_data/twitterscraper/query.py", line 99, in query_single_page
    tweets = list(Tweet.from_html(html))
  File "/home/warproxxx/Desktop/Projects/CryptoTrader/src/data_utils/twitter_data/twitterscraper/tweet.py", line 127, in from_html
    soup = BeautifulSoup(html, "lxml")
  File "/usr/local/lib/python3.7/dist-packages/bs4/__init__.py", line 282, in __init__
    self._feed()
  File "/usr/local/lib/python3.7/dist-packages/bs4/__init__.py", line 343, in _feed
    self.builder.feed(self.markup)
  File "/usr/local/lib/python3.7/dist-packages/bs4/builder/_lxml.py", line 255, in feed
    self.parser.close()
  File "src/lxml/parser.pxi", line 1368, in lxml.etree._FeedParser.close
  File "src/lxml/parser.pxi", line 1399, in lxml.etree._FeedParser.close
  File "src/lxml/parsertarget.pxi", line 148, in lxml.etree._TargetParserContext._handleParseResult
  File "src/lxml/parsertarget.pxi", line 136, in lxml.etree._TargetParserContext._handleParseResult
  File "src/lxml/etree.pyx", line 316, in lxml.etree._ExceptionContext._raise_if_stored
  File "src/lxml/saxparser.pxi", line 389, in lxml.etree._handleSaxTargetStartNoNs
  File "src/lxml/saxparser.pxi", line 404, in lxml.etree._callTargetSaxStart
  File "src/lxml/parsertarget.pxi", line 80, in lxml.etree._PythonSaxParserTarget._handleSaxStart
  File "/usr/local/lib/python3.7/dist-packages/bs4/builder/_lxml.py", line 159, in start
    elif len(nsmap) > 0:
KeyboardInterrupt
Got 59 tweets for bitcoin%20OR%20BTC%20since%3A2015-01-14%20until%3A2015-01-15.
Got 21 tweets for bitcoin%20OR%20BTC%20since%3A2015-01-07%20until%3A2015-01-08.
An unknown error occurred! Returning tweets gathered so far.
Traceback (most recent call last):
  File "/usr/local/lib/python3.7/dist-packages/urllib3/connectionpool.py", line 377, in _make_request
    httplib_response = conn.getresponse(buffering=True)
TypeError: getresponse() got an unexpected keyword argument 'buffering'

During handling of the above exception, another exception occurred:

Traceback (most recent call last):
  File "/home/warproxxx/Desktop/Projects/CryptoTrader/src/data_utils/twitter_data/twitterscraper/query.py", line 158, in query_tweets_once
    pos is None
  File "/home/warproxxx/Desktop/Projects/CryptoTrader/src/data_utils/twitter_data/twitterscraper/query.py", line 89, in query_single_page
    response = requests.get(url, headers=headers)
  File "/usr/local/lib/python3.7/dist-packages/requests/api.py", line 72, in get
    return request('get', url, params=params, **kwargs)
  File "/usr/local/lib/python3.7/dist-packages/requests/api.py", line 58, in request
    return session.request(method=method, url=url, **kwargs)
  File "/usr/local/lib/python3.7/dist-packages/requests/sessions.py", line 512, in request
    resp = self.send(prep, **send_kwargs)
  File "/usr/local/lib/python3.7/dist-packages/requests/sessions.py", line 622, in send
    r = adapter.send(request, **kwargs)
  File "/usr/local/lib/python3.7/dist-packages/requests/adapters.py", line 445, in send
    timeout=timeout
  File "/usr/local/lib/python3.7/dist-packages/urllib3/connectionpool.py", line 600, in urlopen
    chunked=chunked)
  File "/usr/local/lib/python3.7/dist-packages/urllib3/connectionpool.py", line 380, in _make_request
    httplib_response = conn.getresponse()
  File "/usr/lib/python3.7/http/client.py", line 1321, in getresponse
    response.begin()
  File "/usr/lib/python3.7/http/client.py", line 296, in begin
    version, status, reason = self._read_status()
  File "/usr/lib/python3.7/http/client.py", line 257, in _read_status
    line = str(self.fp.readline(_MAXLINE + 1), "iso-8859-1")
  File "/usr/lib/python3.7/socket.py", line 589, in readinto
    return self._sock.recv_into(b)
  File "/usr/lib/python3.7/ssl.py", line 1049, in recv_into
    return self.read(nbytes, buffer)
  File "/usr/lib/python3.7/ssl.py", line 908, in read
    return self._sslobj.read(len, buffer)
KeyboardInterrupt
Got 61 tweets for bitcoin%20OR%20BTC%20since%3A2015-01-08%20until%3A2015-01-09.
An unknown error occurred! Returning tweets gathered so far.
Traceback (most recent call last):
  File "/usr/local/lib/python3.7/dist-packages/urllib3/connectionpool.py", line 377, in _make_request
    httplib_response = conn.getresponse(buffering=True)
TypeError: getresponse() got an unexpected keyword argument 'buffering'

During handling of the above exception, another exception occurred:

Traceback (most recent call last):
  File "/home/warproxxx/Desktop/Projects/CryptoTrader/src/data_utils/twitter_data/twitterscraper/query.py", line 158, in query_tweets_once
    pos is None
  File "/home/warproxxx/Desktop/Projects/CryptoTrader/src/data_utils/twitter_data/twitterscraper/query.py", line 89, in query_single_page
    response = requests.get(url, headers=headers)
  File "/usr/local/lib/python3.7/dist-packages/requests/api.py", line 72, in get
    return request('get', url, params=params, **kwargs)
  File "/usr/local/lib/python3.7/dist-packages/requests/api.py", line 58, in request
    return session.request(method=method, url=url, **kwargs)
  File "/usr/local/lib/python3.7/dist-packages/requests/sessions.py", line 512, in request
    resp = self.send(prep, **send_kwargs)
  File "/usr/local/lib/python3.7/dist-packages/requests/sessions.py", line 622, in send
    r = adapter.send(request, **kwargs)
  File "/usr/local/lib/python3.7/dist-packages/requests/adapters.py", line 445, in send
    timeout=timeout
  File "/usr/local/lib/python3.7/dist-packages/urllib3/connectionpool.py", line 600, in urlopen
    chunked=chunked)
  File "/usr/local/lib/python3.7/dist-packages/urllib3/connectionpool.py", line 380, in _make_request
    httplib_response = conn.getresponse()
  File "/usr/lib/python3.7/http/client.py", line 1321, in getresponse
    response.begin()
  File "/usr/lib/python3.7/http/client.py", line 296, in begin
    version, status, reason = self._read_status()
  File "/usr/lib/python3.7/http/client.py", line 257, in _read_status
    line = str(self.fp.readline(_MAXLINE + 1), "iso-8859-1")
  File "/usr/lib/python3.7/socket.py", line 589, in readinto
    return self._sock.recv_into(b)
  File "/usr/lib/python3.7/ssl.py", line 1049, in recv_into
    return self.read(nbytes, buffer)
  File "/usr/lib/python3.7/ssl.py", line 908, in read
    return self._sslobj.read(len, buffer)
KeyboardInterrupt
Got 59 tweets for bitcoin%20OR%20BTC%20since%3A2015-01-12%20until%3A2015-01-13.
An unknown error occurred! Returning tweets gathered so far.
Traceback (most recent call last):
  File "/usr/local/lib/python3.7/dist-packages/urllib3/connectionpool.py", line 377, in _make_request
    httplib_response = conn.getresponse(buffering=True)
TypeError: getresponse() got an unexpected keyword argument 'buffering'

During handling of the above exception, another exception occurred:

Traceback (most recent call last):
  File "/home/warproxxx/Desktop/Projects/CryptoTrader/src/data_utils/twitter_data/twitterscraper/query.py", line 158, in query_tweets_once
    pos is None
  File "/home/warproxxx/Desktop/Projects/CryptoTrader/src/data_utils/twitter_data/twitterscraper/query.py", line 89, in query_single_page
    response = requests.get(url, headers=headers)
  File "/usr/local/lib/python3.7/dist-packages/requests/api.py", line 72, in get
    return request('get', url, params=params, **kwargs)
  File "/usr/local/lib/python3.7/dist-packages/requests/api.py", line 58, in request
    return session.request(method=method, url=url, **kwargs)
  File "/usr/local/lib/python3.7/dist-packages/requests/sessions.py", line 512, in request
    resp = self.send(prep, **send_kwargs)
  File "/usr/local/lib/python3.7/dist-packages/requests/sessions.py", line 622, in send
    r = adapter.send(request, **kwargs)
  File "/usr/local/lib/python3.7/dist-packages/requests/adapters.py", line 445, in send
    timeout=timeout
  File "/usr/local/lib/python3.7/dist-packages/urllib3/connectionpool.py", line 600, in urlopen
    chunked=chunked)
  File "/usr/local/lib/python3.7/dist-packages/urllib3/connectionpool.py", line 380, in _make_request
    httplib_response = conn.getresponse()
  File "/usr/lib/python3.7/http/client.py", line 1321, in getresponse
    response.begin()
  File "/usr/lib/python3.7/http/client.py", line 296, in begin
    version, status, reason = self._read_status()
  File "/usr/lib/python3.7/http/client.py", line 257, in _read_status
    line = str(self.fp.readline(_MAXLINE + 1), "iso-8859-1")
  File "/usr/lib/python3.7/socket.py", line 589, in readinto
    return self._sock.recv_into(b)
  File "/usr/lib/python3.7/ssl.py", line 1049, in recv_into
    return self.read(nbytes, buffer)
  File "/usr/lib/python3.7/ssl.py", line 908, in read
    return self._sslobj.read(len, buffer)
KeyboardInterrupt
Got 59 tweets for bitcoin%20OR%20BTC%20since%3A2015-01-03%20until%3A2015-01-04.
An unknown error occurred! Returning tweets gathered so far.
Traceback (most recent call last):
  File "/usr/local/lib/python3.7/dist-packages/urllib3/connectionpool.py", line 377, in _make_request
    httplib_response = conn.getresponse(buffering=True)
TypeError: getresponse() got an unexpected keyword argument 'buffering'

During handling of the above exception, another exception occurred:

Traceback (most recent call last):
  File "/home/warproxxx/Desktop/Projects/CryptoTrader/src/data_utils/twitter_data/twitterscraper/query.py", line 158, in query_tweets_once
    pos is None
  File "/home/warproxxx/Desktop/Projects/CryptoTrader/src/data_utils/twitter_data/twitterscraper/query.py", line 89, in query_single_page
    response = requests.get(url, headers=headers)
  File "/usr/local/lib/python3.7/dist-packages/requests/api.py", line 72, in get
    return request('get', url, params=params, **kwargs)
  File "/usr/local/lib/python3.7/dist-packages/requests/api.py", line 58, in request
    return session.request(method=method, url=url, **kwargs)
  File "/usr/local/lib/python3.7/dist-packages/requests/sessions.py", line 512, in request
    resp = self.send(prep, **send_kwargs)
  File "/usr/local/lib/python3.7/dist-packages/requests/sessions.py", line 622, in send
    r = adapter.send(request, **kwargs)
  File "/usr/local/lib/python3.7/dist-packages/requests/adapters.py", line 445, in send
    timeout=timeout
  File "/usr/local/lib/python3.7/dist-packages/urllib3/connectionpool.py", line 600, in urlopen
    chunked=chunked)
  File "/usr/local/lib/python3.7/dist-packages/urllib3/connectionpool.py", line 380, in _make_request
    httplib_response = conn.getresponse()
  File "/usr/lib/python3.7/http/client.py", line 1321, in getresponse
    response.begin()
  File "/usr/lib/python3.7/http/client.py", line 296, in begin
    version, status, reason = self._read_status()
  File "/usr/lib/python3.7/http/client.py", line 257, in _read_status
    line = str(self.fp.readline(_MAXLINE + 1), "iso-8859-1")
  File "/usr/lib/python3.7/socket.py", line 589, in readinto
    return self._sock.recv_into(b)
  File "/usr/lib/python3.7/ssl.py", line 1049, in recv_into
    return self.read(nbytes, buffer)
  File "/usr/lib/python3.7/ssl.py", line 908, in read
    return self._sslobj.read(len, buffer)
KeyboardInterrupt
An unknown error occurred! Returning tweets gathered so far.
Traceback (most recent call last):
  File "/usr/local/lib/python3.7/dist-packages/urllib3/connectionpool.py", line 377, in _make_request
    httplib_response = conn.getresponse(buffering=True)
TypeError: getresponse() got an unexpected keyword argument 'buffering'

During handling of the above exception, another exception occurred:

Traceback (most recent call last):
  File "/home/warproxxx/Desktop/Projects/CryptoTrader/src/data_utils/twitter_data/twitterscraper/query.py", line 158, in query_tweets_once
    pos is None
  File "/home/warproxxx/Desktop/Projects/CryptoTrader/src/data_utils/twitter_data/twitterscraper/query.py", line 89, in query_single_page
    response = requests.get(url, headers=headers)
  File "/usr/local/lib/python3.7/dist-packages/requests/api.py", line 72, in get
    return request('get', url, params=params, **kwargs)
  File "/usr/local/lib/python3.7/dist-packages/requests/api.py", line 58, in request
    return session.request(method=method, url=url, **kwargs)
  File "/usr/local/lib/python3.7/dist-packages/requests/sessions.py", line 512, in request
    resp = self.send(prep, **send_kwargs)
  File "/usr/local/lib/python3.7/dist-packages/requests/sessions.py", line 622, in send
    r = adapter.send(request, **kwargs)
  File "/usr/local/lib/python3.7/dist-packages/requests/adapters.py", line 445, in send
    timeout=timeout
  File "/usr/local/lib/python3.7/dist-packages/urllib3/connectionpool.py", line 600, in urlopen
    chunked=chunked)
  File "/usr/local/lib/python3.7/dist-packages/urllib3/connectionpool.py", line 380, in _make_request
    httplib_response = conn.getresponse()
  File "/usr/lib/python3.7/http/client.py", line 1321, in getresponse
    response.begin()
  File "/usr/lib/python3.7/http/client.py", line 296, in begin
    version, status, reason = self._read_status()
  File "/usr/lib/python3.7/http/client.py", line 257, in _read_status
    line = str(self.fp.readline(_MAXLINE + 1), "iso-8859-1")
  File "/usr/lib/python3.7/socket.py", line 589, in readinto
    return self._sock.recv_into(b)
  File "/usr/lib/python3.7/ssl.py", line 1049, in recv_into
    return self.read(nbytes, buffer)
  File "/usr/lib/python3.7/ssl.py", line 908, in read
    return self._sslobj.read(len, buffer)
KeyboardInterrupt
Got 61 tweets for bitcoin%20OR%20BTC%20since%3A2015-01-06%20until%3A2015-01-07.
An unknown error occurred! Returning tweets gathered so far.
Traceback (most recent call last):
  File "/home/warproxxx/Desktop/Projects/CryptoTrader/src/data_utils/twitter_data/twitterscraper/query.py", line 158, in query_tweets_once
    pos is None
  File "/home/warproxxx/Desktop/Projects/CryptoTrader/src/data_utils/twitter_data/twitterscraper/query.py", line 89, in query_single_page
    response = requests.get(url, headers=headers)
  File "/usr/local/lib/python3.7/dist-packages/requests/api.py", line 72, in get
    return request('get', url, params=params, **kwargs)
  File "/usr/local/lib/python3.7/dist-packages/requests/api.py", line 58, in request
    return session.request(method=method, url=url, **kwargs)
  File "/usr/local/lib/python3.7/dist-packages/requests/sessions.py", line 512, in request
    resp = self.send(prep, **send_kwargs)
  File "/usr/local/lib/python3.7/dist-packages/requests/sessions.py", line 662, in send
    r.content
  File "/usr/local/lib/python3.7/dist-packages/requests/models.py", line 827, in content
    self._content = b''.join(self.iter_content(CONTENT_CHUNK_SIZE)) or b''
  File "/usr/local/lib/python3.7/dist-packages/requests/models.py", line 749, in generate
    for chunk in self.raw.stream(chunk_size, decode_content=True):
  File "/usr/local/lib/python3.7/dist-packages/urllib3/response.py", line 465, in stream
    data = self.read(amt=amt, decode_content=decode_content)
  File "/usr/local/lib/python3.7/dist-packages/urllib3/response.py", line 413, in read
    data = self._fp.read(amt)
  File "/usr/lib/python3.7/http/client.py", line 447, in read
    n = self.readinto(b)
  File "/usr/lib/python3.7/http/client.py", line 491, in readinto
    n = self.fp.readinto(b)
  File "/usr/lib/python3.7/socket.py", line 589, in readinto
    return self._sock.recv_into(b)
  File "/usr/lib/python3.7/ssl.py", line 1049, in recv_into
    return self.read(nbytes, buffer)
  File "/usr/lib/python3.7/ssl.py", line 908, in read
    return self._sslobj.read(len, buffer)
KeyboardInterrupt
Got 60 tweets for bitcoin%20OR%20BTC%20since%3A2015-01-05%20until%3A2015-01-06.
An unknown error occurred! Returning tweets gathered so far.
Traceback (most recent call last):
  File "/usr/local/lib/python3.7/dist-packages/urllib3/connectionpool.py", line 377, in _make_request
    httplib_response = conn.getresponse(buffering=True)
TypeError: getresponse() got an unexpected keyword argument 'buffering'

During handling of the above exception, another exception occurred:

Traceback (most recent call last):
  File "/home/warproxxx/Desktop/Projects/CryptoTrader/src/data_utils/twitter_data/twitterscraper/query.py", line 158, in query_tweets_once
    pos is None
  File "/home/warproxxx/Desktop/Projects/CryptoTrader/src/data_utils/twitter_data/twitterscraper/query.py", line 89, in query_single_page
    response = requests.get(url, headers=headers)
  File "/usr/local/lib/python3.7/dist-packages/requests/api.py", line 72, in get
    return request('get', url, params=params, **kwargs)
  File "/usr/local/lib/python3.7/dist-packages/requests/api.py", line 58, in request
    return session.request(method=method, url=url, **kwargs)
  File "/usr/local/lib/python3.7/dist-packages/requests/sessions.py", line 512, in request
    resp = self.send(prep, **send_kwargs)
  File "/usr/local/lib/python3.7/dist-packages/requests/sessions.py", line 622, in send
    r = adapter.send(request, **kwargs)
  File "/usr/local/lib/python3.7/dist-packages/requests/adapters.py", line 445, in send
    timeout=timeout
  File "/usr/local/lib/python3.7/dist-packages/urllib3/connectionpool.py", line 600, in urlopen
    chunked=chunked)
  File "/usr/local/lib/python3.7/dist-packages/urllib3/connectionpool.py", line 380, in _make_request
    httplib_response = conn.getresponse()
  File "/usr/lib/python3.7/http/client.py", line 1321, in getresponse
    response.begin()
  File "/usr/lib/python3.7/http/client.py", line 296, in begin
    version, status, reason = self._read_status()
  File "/usr/lib/python3.7/http/client.py", line 257, in _read_status
    line = str(self.fp.readline(_MAXLINE + 1), "iso-8859-1")
  File "/usr/lib/python3.7/socket.py", line 589, in readinto
    return self._sock.recv_into(b)
  File "/usr/lib/python3.7/ssl.py", line 1049, in recv_into
    return self.read(nbytes, buffer)
  File "/usr/lib/python3.7/ssl.py", line 908, in read
    return self._sslobj.read(len, buffer)
KeyboardInterrupt
Got 60 tweets for bitcoin%20OR%20BTC%20since%3A2015-01-18%20until%3A2015-01-19.
An unknown error occurred! Returning tweets gathered so far.
Traceback (most recent call last):
  File "/home/warproxxx/Desktop/Projects/CryptoTrader/src/data_utils/twitter_data/twitterscraper/query.py", line 158, in query_tweets_once
    pos is None
  File "/home/warproxxx/Desktop/Projects/CryptoTrader/src/data_utils/twitter_data/twitterscraper/query.py", line 89, in query_single_page
    response = requests.get(url, headers=headers)
  File "/usr/local/lib/python3.7/dist-packages/requests/api.py", line 72, in get
    return request('get', url, params=params, **kwargs)
  File "/usr/local/lib/python3.7/dist-packages/requests/api.py", line 58, in request
    return session.request(method=method, url=url, **kwargs)
  File "/usr/local/lib/python3.7/dist-packages/requests/sessions.py", line 512, in request
    resp = self.send(prep, **send_kwargs)
  File "/usr/local/lib/python3.7/dist-packages/requests/sessions.py", line 662, in send
    r.content
  File "/usr/local/lib/python3.7/dist-packages/requests/models.py", line 827, in content
    self._content = b''.join(self.iter_content(CONTENT_CHUNK_SIZE)) or b''
  File "/usr/local/lib/python3.7/dist-packages/requests/models.py", line 749, in generate
    for chunk in self.raw.stream(chunk_size, decode_content=True):
  File "/usr/local/lib/python3.7/dist-packages/urllib3/response.py", line 465, in stream
    data = self.read(amt=amt, decode_content=decode_content)
  File "/usr/local/lib/python3.7/dist-packages/urllib3/response.py", line 413, in read
    data = self._fp.read(amt)
  File "/usr/lib/python3.7/http/client.py", line 447, in read
    n = self.readinto(b)
  File "/usr/lib/python3.7/http/client.py", line 491, in readinto
    n = self.fp.readinto(b)
  File "/usr/lib/python3.7/socket.py", line 589, in readinto
    return self._sock.recv_into(b)
  File "/usr/lib/python3.7/ssl.py", line 1049, in recv_into
    return self.read(nbytes, buffer)
  File "/usr/lib/python3.7/ssl.py", line 908, in read
    return self._sslobj.read(len, buffer)
KeyboardInterrupt
Got 60 tweets for bitcoin%20OR%20BTC%20since%3A2015-01-13%20until%3A2015-01-14.
An unknown error occurred! Returning tweets gathered so far.
Traceback (most recent call last):
  File "/home/warproxxx/Desktop/Projects/CryptoTrader/src/data_utils/twitter_data/twitterscraper/query.py", line 158, in query_tweets_once
    pos is None
  File "/home/warproxxx/Desktop/Projects/CryptoTrader/src/data_utils/twitter_data/twitterscraper/query.py", line 89, in query_single_page
    response = requests.get(url, headers=headers)
  File "/usr/local/lib/python3.7/dist-packages/requests/api.py", line 72, in get
    return request('get', url, params=params, **kwargs)
  File "/usr/local/lib/python3.7/dist-packages/requests/api.py", line 58, in request
    return session.request(method=method, url=url, **kwargs)
  File "/usr/local/lib/python3.7/dist-packages/requests/sessions.py", line 512, in request
    resp = self.send(prep, **send_kwargs)
  File "/usr/local/lib/python3.7/dist-packages/requests/sessions.py", line 662, in send
    r.content
  File "/usr/local/lib/python3.7/dist-packages/requests/models.py", line 827, in content
    self._content = b''.join(self.iter_content(CONTENT_CHUNK_SIZE)) or b''
  File "/usr/local/lib/python3.7/dist-packages/requests/models.py", line 749, in generate
    for chunk in self.raw.stream(chunk_size, decode_content=True):
  File "/usr/local/lib/python3.7/dist-packages/urllib3/response.py", line 465, in stream
    data = self.read(amt=amt, decode_content=decode_content)
  File "/usr/local/lib/python3.7/dist-packages/urllib3/response.py", line 413, in read
    data = self._fp.read(amt)
  File "/usr/lib/python3.7/http/client.py", line 447, in read
    n = self.readinto(b)
  File "/usr/lib/python3.7/http/client.py", line 491, in readinto
    n = self.fp.readinto(b)
  File "/usr/lib/python3.7/socket.py", line 589, in readinto
    return self._sock.recv_into(b)
  File "/usr/lib/python3.7/ssl.py", line 1049, in recv_into
    return self.read(nbytes, buffer)
  File "/usr/lib/python3.7/ssl.py", line 908, in read
    return self._sslobj.read(len, buffer)
KeyboardInterrupt
Got 61 tweets for bitcoin%20OR%20BTC%20since%3A2015-01-01%20until%3A2015-01-02.
Got 59 tweets for bitcoin%20OR%20BTC%20since%3A2015-01-04%20until%3A2015-01-05.
Got 60 tweets for bitcoin%20OR%20BTC%20since%3A2015-01-15%20until%3A2015-01-16.
An unknown error occurred! Returning tweets gathered so far.
Traceback (most recent call last):
  File "/home/warproxxx/Desktop/Projects/CryptoTrader/src/data_utils/twitter_data/twitterscraper/query.py", line 158, in query_tweets_once
    pos is None
  File "/home/warproxxx/Desktop/Projects/CryptoTrader/src/data_utils/twitter_data/twitterscraper/query.py", line 125, in query_single_page
    return self.query_single_page(url, html_response, retry-1)
  File "/home/warproxxx/Desktop/Projects/CryptoTrader/src/data_utils/twitter_data/twitterscraper/query.py", line 89, in query_single_page
    response = requests.get(url, headers=headers)
  File "/usr/local/lib/python3.7/dist-packages/requests/api.py", line 72, in get
    return request('get', url, params=params, **kwargs)
  File "/usr/local/lib/python3.7/dist-packages/requests/api.py", line 58, in request
    return session.request(method=method, url=url, **kwargs)
  File "/usr/local/lib/python3.7/dist-packages/requests/sessions.py", line 512, in request
    resp = self.send(prep, **send_kwargs)
  File "/usr/local/lib/python3.7/dist-packages/requests/sessions.py", line 622, in send
    r = adapter.send(request, **kwargs)
  File "/usr/local/lib/python3.7/dist-packages/requests/adapters.py", line 445, in send
    timeout=timeout
  File "/usr/local/lib/python3.7/dist-packages/urllib3/connectionpool.py", line 600, in urlopen
    chunked=chunked)
  File "/usr/local/lib/python3.7/dist-packages/urllib3/connectionpool.py", line 343, in _make_request
    self._validate_conn(conn)
  File "/usr/local/lib/python3.7/dist-packages/urllib3/connectionpool.py", line 849, in _validate_conn
    conn.connect()
  File "/usr/local/lib/python3.7/dist-packages/urllib3/connection.py", line 314, in connect
    conn = self._new_conn()
  File "/usr/local/lib/python3.7/dist-packages/urllib3/connection.py", line 171, in _new_conn
    (self._dns_host, self.port), self.timeout, **extra_kw)
  File "/usr/local/lib/python3.7/dist-packages/urllib3/util/connection.py", line 69, in create_connection
    sock.connect(sa)
KeyboardInterrupt
Got 61 tweets for bitcoin%20OR%20BTC%20since%3A2015-01-10%20until%3A2015-01-11.
An unknown error occurred! Returning tweets gathered so far.
Traceback (most recent call last):
  File "/home/warproxxx/Desktop/Projects/CryptoTrader/src/data_utils/twitter_data/twitterscraper/query.py", line 158, in query_tweets_once
    pos is None
  File "/home/warproxxx/Desktop/Projects/CryptoTrader/src/data_utils/twitter_data/twitterscraper/query.py", line 89, in query_single_page
    response = requests.get(url, headers=headers)
  File "/usr/local/lib/python3.7/dist-packages/requests/api.py", line 72, in get
    return request('get', url, params=params, **kwargs)
  File "/usr/local/lib/python3.7/dist-packages/requests/api.py", line 58, in request
    return session.request(method=method, url=url, **kwargs)
  File "/usr/local/lib/python3.7/dist-packages/requests/sessions.py", line 512, in request
    resp = self.send(prep, **send_kwargs)
  File "/usr/local/lib/python3.7/dist-packages/requests/sessions.py", line 622, in send
    r = adapter.send(request, **kwargs)
  File "/usr/local/lib/python3.7/dist-packages/requests/adapters.py", line 445, in send
    timeout=timeout
  File "/usr/local/lib/python3.7/dist-packages/urllib3/connectionpool.py", line 600, in urlopen
    chunked=chunked)
  File "/usr/local/lib/python3.7/dist-packages/urllib3/connectionpool.py", line 343, in _make_request
    self._validate_conn(conn)
  File "/usr/local/lib/python3.7/dist-packages/urllib3/connectionpool.py", line 849, in _validate_conn
    conn.connect()
  File "/usr/local/lib/python3.7/dist-packages/urllib3/connection.py", line 314, in connect
    conn = self._new_conn()
  File "/usr/local/lib/python3.7/dist-packages/urllib3/connection.py", line 171, in _new_conn
    (self._dns_host, self.port), self.timeout, **extra_kw)
  File "/usr/local/lib/python3.7/dist-packages/urllib3/util/connection.py", line 69, in create_connection
    sock.connect(sa)
KeyboardInterrupt
Got 21 tweets for bitcoin%20OR%20BTC%20since%3A2015-01-26%20until%3A2015-01-27.
An unknown error occurred! Returning tweets gathered so far.
Traceback (most recent call last):
  File "/home/warproxxx/Desktop/Projects/CryptoTrader/src/data_utils/twitter_data/twitterscraper/query.py", line 158, in query_tweets_once
    pos is None
  File "/home/warproxxx/Desktop/Projects/CryptoTrader/src/data_utils/twitter_data/twitterscraper/query.py", line 89, in query_single_page
    response = requests.get(url, headers=headers)
  File "/usr/local/lib/python3.7/dist-packages/requests/api.py", line 72, in get
    return request('get', url, params=params, **kwargs)
  File "/usr/local/lib/python3.7/dist-packages/requests/api.py", line 58, in request
    return session.request(method=method, url=url, **kwargs)
  File "/usr/local/lib/python3.7/dist-packages/requests/sessions.py", line 512, in request
    resp = self.send(prep, **send_kwargs)
  File "/usr/local/lib/python3.7/dist-packages/requests/sessions.py", line 622, in send
    r = adapter.send(request, **kwargs)
  File "/usr/local/lib/python3.7/dist-packages/requests/adapters.py", line 445, in send
    timeout=timeout
  File "/usr/local/lib/python3.7/dist-packages/urllib3/connectionpool.py", line 600, in urlopen
    chunked=chunked)
  File "/usr/local/lib/python3.7/dist-packages/urllib3/connectionpool.py", line 343, in _make_request
    self._validate_conn(conn)
  File "/usr/local/lib/python3.7/dist-packages/urllib3/connectionpool.py", line 849, in _validate_conn
    conn.connect()
  File "/usr/local/lib/python3.7/dist-packages/urllib3/connection.py", line 314, in connect
    conn = self._new_conn()
  File "/usr/local/lib/python3.7/dist-packages/urllib3/connection.py", line 171, in _new_conn
    (self._dns_host, self.port), self.timeout, **extra_kw)
  File "/usr/local/lib/python3.7/dist-packages/urllib3/util/connection.py", line 69, in create_connection
    sock.connect(sa)
KeyboardInterrupt
Got 21 tweets for bitcoin%20OR%20BTC%20since%3A2015-01-23%20until%3A2015-01-24.
An unknown error occurred! Returning tweets gathered so far.
Traceback (most recent call last):
  File "/home/warproxxx/Desktop/Projects/CryptoTrader/src/data_utils/twitter_data/twitterscraper/query.py", line 158, in query_tweets_once
    pos is None
  File "/home/warproxxx/Desktop/Projects/CryptoTrader/src/data_utils/twitter_data/twitterscraper/query.py", line 89, in query_single_page
    response = requests.get(url, headers=headers)
  File "/usr/local/lib/python3.7/dist-packages/requests/api.py", line 72, in get
    return request('get', url, params=params, **kwargs)
  File "/usr/local/lib/python3.7/dist-packages/requests/api.py", line 58, in request
    return session.request(method=method, url=url, **kwargs)
  File "/usr/local/lib/python3.7/dist-packages/requests/sessions.py", line 512, in request
    resp = self.send(prep, **send_kwargs)
  File "/usr/local/lib/python3.7/dist-packages/requests/sessions.py", line 622, in send
    r = adapter.send(request, **kwargs)
  File "/usr/local/lib/python3.7/dist-packages/requests/adapters.py", line 445, in send
    timeout=timeout
  File "/usr/local/lib/python3.7/dist-packages/urllib3/connectionpool.py", line 600, in urlopen
    chunked=chunked)
  File "/usr/local/lib/python3.7/dist-packages/urllib3/connectionpool.py", line 343, in _make_request
    self._validate_conn(conn)
  File "/usr/local/lib/python3.7/dist-packages/urllib3/connectionpool.py", line 849, in _validate_conn
    conn.connect()
  File "/usr/local/lib/python3.7/dist-packages/urllib3/connection.py", line 356, in connect
    ssl_context=context)
  File "/usr/local/lib/python3.7/dist-packages/urllib3/util/ssl_.py", line 359, in ssl_wrap_socket
    return context.wrap_socket(sock, server_hostname=server_hostname)
  File "/usr/lib/python3.7/ssl.py", line 412, in wrap_socket
    session=session
  File "/usr/lib/python3.7/ssl.py", line 850, in _create
    self.do_handshake()
  File "/usr/lib/python3.7/ssl.py", line 1108, in do_handshake
    self._sslobj.do_handshake()
KeyboardInterrupt
Got 21 tweets for bitcoin%20OR%20BTC%20since%3A2015-01-22%20until%3A2015-01-23.
An unknown error occurred! Returning tweets gathered so far.
Traceback (most recent call last):
  File "/home/warproxxx/Desktop/Projects/CryptoTrader/src/data_utils/twitter_data/twitterscraper/query.py", line 158, in query_tweets_once
    pos is None
  File "/home/warproxxx/Desktop/Projects/CryptoTrader/src/data_utils/twitter_data/twitterscraper/query.py", line 89, in query_single_page
    response = requests.get(url, headers=headers)
  File "/usr/local/lib/python3.7/dist-packages/requests/api.py", line 72, in get
    return request('get', url, params=params, **kwargs)
  File "/usr/local/lib/python3.7/dist-packages/requests/api.py", line 58, in request
    return session.request(method=method, url=url, **kwargs)
  File "/usr/local/lib/python3.7/dist-packages/requests/sessions.py", line 512, in request
    resp = self.send(prep, **send_kwargs)
  File "/usr/local/lib/python3.7/dist-packages/requests/sessions.py", line 622, in send
    r = adapter.send(request, **kwargs)
  File "/usr/local/lib/python3.7/dist-packages/requests/adapters.py", line 445, in send
    timeout=timeout
  File "/usr/local/lib/python3.7/dist-packages/urllib3/connectionpool.py", line 600, in urlopen
    chunked=chunked)
  File "/usr/local/lib/python3.7/dist-packages/urllib3/connectionpool.py", line 343, in _make_request
    self._validate_conn(conn)
  File "/usr/local/lib/python3.7/dist-packages/urllib3/connectionpool.py", line 849, in _validate_conn
    conn.connect()
  File "/usr/local/lib/python3.7/dist-packages/urllib3/connection.py", line 314, in connect
    conn = self._new_conn()
  File "/usr/local/lib/python3.7/dist-packages/urllib3/connection.py", line 171, in _new_conn
    (self._dns_host, self.port), self.timeout, **extra_kw)
  File "/usr/local/lib/python3.7/dist-packages/urllib3/util/connection.py", line 56, in create_connection
    for res in socket.getaddrinfo(host, port, family, socket.SOCK_STREAM):
  File "/usr/lib/python3.7/socket.py", line 748, in getaddrinfo
    for res in _socket.getaddrinfo(host, port, family, type, proto, flags):
KeyboardInterrupt
Got 0 tweets for bitcoin%20OR%20BTC%20since%3A2015-01-19%20until%3A2015-01-20.
An unknown error occurred! Returning tweets gathered so far.
Traceback (most recent call last):
  File "/home/warproxxx/Desktop/Projects/CryptoTrader/src/data_utils/twitter_data/twitterscraper/query.py", line 158, in query_tweets_once
    pos is None
  File "/home/warproxxx/Desktop/Projects/CryptoTrader/src/data_utils/twitter_data/twitterscraper/query.py", line 89, in query_single_page
    response = requests.get(url, headers=headers)
  File "/usr/local/lib/python3.7/dist-packages/requests/api.py", line 72, in get
    return request('get', url, params=params, **kwargs)
  File "/usr/local/lib/python3.7/dist-packages/requests/api.py", line 58, in request
    return session.request(method=method, url=url, **kwargs)
  File "/usr/local/lib/python3.7/dist-packages/requests/sessions.py", line 512, in request
    resp = self.send(prep, **send_kwargs)
  File "/usr/local/lib/python3.7/dist-packages/requests/sessions.py", line 622, in send
    r = adapter.send(request, **kwargs)
  File "/usr/local/lib/python3.7/dist-packages/requests/adapters.py", line 445, in send
    timeout=timeout
  File "/usr/local/lib/python3.7/dist-packages/urllib3/connectionpool.py", line 600, in urlopen
    chunked=chunked)
  File "/usr/local/lib/python3.7/dist-packages/urllib3/connectionpool.py", line 343, in _make_request
    self._validate_conn(conn)
  File "/usr/local/lib/python3.7/dist-packages/urllib3/connectionpool.py", line 849, in _validate_conn
    conn.connect()
  File "/usr/local/lib/python3.7/dist-packages/urllib3/connection.py", line 314, in connect
    conn = self._new_conn()
  File "/usr/local/lib/python3.7/dist-packages/urllib3/connection.py", line 171, in _new_conn
    (self._dns_host, self.port), self.timeout, **extra_kw)
  File "/usr/local/lib/python3.7/dist-packages/urllib3/util/connection.py", line 56, in create_connection
    for res in socket.getaddrinfo(host, port, family, socket.SOCK_STREAM):
  File "/usr/lib/python3.7/socket.py", line 748, in getaddrinfo
    for res in _socket.getaddrinfo(host, port, family, type, proto, flags):
KeyboardInterrupt
Got 0 tweets for bitcoin%20OR%20BTC%20since%3A2015-01-17%20until%3A2015-01-18.
An unknown error occurred! Returning tweets gathered so far.
Traceback (most recent call last):
  File "/home/warproxxx/Desktop/Projects/CryptoTrader/src/data_utils/twitter_data/twitterscraper/query.py", line 158, in query_tweets_once
    pos is None
  File "/home/warproxxx/Desktop/Projects/CryptoTrader/src/data_utils/twitter_data/twitterscraper/query.py", line 89, in query_single_page
    response = requests.get(url, headers=headers)
  File "/usr/local/lib/python3.7/dist-packages/requests/api.py", line 72, in get
    return request('get', url, params=params, **kwargs)
  File "/usr/local/lib/python3.7/dist-packages/requests/api.py", line 58, in request
    return session.request(method=method, url=url, **kwargs)
  File "/usr/local/lib/python3.7/dist-packages/requests/sessions.py", line 512, in request
    resp = self.send(prep, **send_kwargs)
  File "/usr/local/lib/python3.7/dist-packages/requests/sessions.py", line 622, in send
    r = adapter.send(request, **kwargs)
  File "/usr/local/lib/python3.7/dist-packages/requests/adapters.py", line 445, in send
    timeout=timeout
  File "/usr/local/lib/python3.7/dist-packages/urllib3/connectionpool.py", line 600, in urlopen
    chunked=chunked)
  File "/usr/local/lib/python3.7/dist-packages/urllib3/connectionpool.py", line 343, in _make_request
    self._validate_conn(conn)
  File "/usr/local/lib/python3.7/dist-packages/urllib3/connectionpool.py", line 849, in _validate_conn
    conn.connect()
  File "/usr/local/lib/python3.7/dist-packages/urllib3/connection.py", line 314, in connect
    conn = self._new_conn()
  File "/usr/local/lib/python3.7/dist-packages/urllib3/connection.py", line 171, in _new_conn
    (self._dns_host, self.port), self.timeout, **extra_kw)
  File "/usr/local/lib/python3.7/dist-packages/urllib3/util/connection.py", line 56, in create_connection
    for res in socket.getaddrinfo(host, port, family, socket.SOCK_STREAM):
  File "/usr/lib/python3.7/socket.py", line 748, in getaddrinfo
    for res in _socket.getaddrinfo(host, port, family, type, proto, flags):
KeyboardInterrupt
Got 0 tweets for bitcoin%20OR%20BTC%20since%3A2015-01-28%20until%3A2015-01-29.
An unknown error occurred! Returning tweets gathered so far.
Traceback (most recent call last):
  File "/home/warproxxx/Desktop/Projects/CryptoTrader/src/data_utils/twitter_data/twitterscraper/query.py", line 158, in query_tweets_once
    pos is None
  File "/home/warproxxx/Desktop/Projects/CryptoTrader/src/data_utils/twitter_data/twitterscraper/query.py", line 89, in query_single_page
    response = requests.get(url, headers=headers)
  File "/usr/local/lib/python3.7/dist-packages/requests/api.py", line 72, in get
    return request('get', url, params=params, **kwargs)
  File "/usr/local/lib/python3.7/dist-packages/requests/api.py", line 58, in request
    return session.request(method=method, url=url, **kwargs)
  File "/usr/local/lib/python3.7/dist-packages/requests/sessions.py", line 512, in request
    resp = self.send(prep, **send_kwargs)
  File "/usr/local/lib/python3.7/dist-packages/requests/sessions.py", line 622, in send
    r = adapter.send(request, **kwargs)
  File "/usr/local/lib/python3.7/dist-packages/requests/adapters.py", line 445, in send
    timeout=timeout
  File "/usr/local/lib/python3.7/dist-packages/urllib3/connectionpool.py", line 600, in urlopen
    chunked=chunked)
  File "/usr/local/lib/python3.7/dist-packages/urllib3/connectionpool.py", line 343, in _make_request
    self._validate_conn(conn)
  File "/usr/local/lib/python3.7/dist-packages/urllib3/connectionpool.py", line 849, in _validate_conn
    conn.connect()
  File "/usr/local/lib/python3.7/dist-packages/urllib3/connection.py", line 314, in connect
    conn = self._new_conn()
  File "/usr/local/lib/python3.7/dist-packages/urllib3/connection.py", line 171, in _new_conn
    (self._dns_host, self.port), self.timeout, **extra_kw)
  File "/usr/local/lib/python3.7/dist-packages/urllib3/util/connection.py", line 56, in create_connection
    for res in socket.getaddrinfo(host, port, family, socket.SOCK_STREAM):
  File "/usr/lib/python3.7/socket.py", line 748, in getaddrinfo
    for res in _socket.getaddrinfo(host, port, family, type, proto, flags):
KeyboardInterrupt
Got 0 tweets for bitcoin%20OR%20BTC%20since%3A2015-01-27%20until%3A2015-01-28.
An unknown error occurred! Returning tweets gathered so far.
Traceback (most recent call last):
  File "/home/warproxxx/Desktop/Projects/CryptoTrader/src/data_utils/twitter_data/twitterscraper/query.py", line 158, in query_tweets_once
    pos is None
  File "/home/warproxxx/Desktop/Projects/CryptoTrader/src/data_utils/twitter_data/twitterscraper/query.py", line 89, in query_single_page
    response = requests.get(url, headers=headers)
  File "/usr/local/lib/python3.7/dist-packages/requests/api.py", line 72, in get
    return request('get', url, params=params, **kwargs)
  File "/usr/local/lib/python3.7/dist-packages/requests/api.py", line 58, in request
    return session.request(method=method, url=url, **kwargs)
  File "/usr/local/lib/python3.7/dist-packages/requests/sessions.py", line 512, in request
    resp = self.send(prep, **send_kwargs)
  File "/usr/local/lib/python3.7/dist-packages/requests/sessions.py", line 622, in send
    r = adapter.send(request, **kwargs)
  File "/usr/local/lib/python3.7/dist-packages/requests/adapters.py", line 445, in send
    timeout=timeout
  File "/usr/local/lib/python3.7/dist-packages/urllib3/connectionpool.py", line 600, in urlopen
    chunked=chunked)
  File "/usr/local/lib/python3.7/dist-packages/urllib3/connectionpool.py", line 343, in _make_request
    self._validate_conn(conn)
  File "/usr/local/lib/python3.7/dist-packages/urllib3/connectionpool.py", line 849, in _validate_conn
    conn.connect()
  File "/usr/local/lib/python3.7/dist-packages/urllib3/connection.py", line 314, in connect
    conn = self._new_conn()
  File "/usr/local/lib/python3.7/dist-packages/urllib3/connection.py", line 171, in _new_conn
    (self._dns_host, self.port), self.timeout, **extra_kw)
  File "/usr/local/lib/python3.7/dist-packages/urllib3/util/connection.py", line 56, in create_connection
    for res in socket.getaddrinfo(host, port, family, socket.SOCK_STREAM):
  File "/usr/lib/python3.7/socket.py", line 748, in getaddrinfo
    for res in _socket.getaddrinfo(host, port, family, type, proto, flags):
KeyboardInterrupt
Got 0 tweets for bitcoin%20OR%20BTC%20since%3A2015-01-29%20until%3A2015-01-30.
An unknown error occurred! Returning tweets gathered so far.
Traceback (most recent call last):
  File "/home/warproxxx/Desktop/Projects/CryptoTrader/src/data_utils/twitter_data/twitterscraper/query.py", line 158, in query_tweets_once
    pos is None
  File "/home/warproxxx/Desktop/Projects/CryptoTrader/src/data_utils/twitter_data/twitterscraper/query.py", line 89, in query_single_page
    response = requests.get(url, headers=headers)
  File "/usr/local/lib/python3.7/dist-packages/requests/api.py", line 72, in get
    return request('get', url, params=params, **kwargs)
  File "/usr/local/lib/python3.7/dist-packages/requests/api.py", line 58, in request
    return session.request(method=method, url=url, **kwargs)
  File "/usr/local/lib/python3.7/dist-packages/requests/sessions.py", line 512, in request
    resp = self.send(prep, **send_kwargs)
  File "/usr/local/lib/python3.7/dist-packages/requests/sessions.py", line 622, in send
    r = adapter.send(request, **kwargs)
  File "/usr/local/lib/python3.7/dist-packages/requests/adapters.py", line 445, in send
    timeout=timeout
  File "/usr/local/lib/python3.7/dist-packages/urllib3/connectionpool.py", line 600, in urlopen
    chunked=chunked)
  File "/usr/local/lib/python3.7/dist-packages/urllib3/connectionpool.py", line 343, in _make_request
    self._validate_conn(conn)
  File "/usr/local/lib/python3.7/dist-packages/urllib3/connectionpool.py", line 849, in _validate_conn
    conn.connect()
  File "/usr/local/lib/python3.7/dist-packages/urllib3/connection.py", line 314, in connect
    conn = self._new_conn()
  File "/usr/local/lib/python3.7/dist-packages/urllib3/connection.py", line 171, in _new_conn
    (self._dns_host, self.port), self.timeout, **extra_kw)
  File "/usr/local/lib/python3.7/dist-packages/urllib3/util/connection.py", line 56, in create_connection
    for res in socket.getaddrinfo(host, port, family, socket.SOCK_STREAM):
  File "/usr/lib/python3.7/socket.py", line 748, in getaddrinfo
    for res in _socket.getaddrinfo(host, port, family, type, proto, flags):
KeyboardInterrupt
Got 0 tweets for bitcoin%20OR%20BTC%20since%3A2015-01-31%20until%3A2015-02-01.
An unknown error occurred! Returning tweets gathered so far.
Traceback (most recent call last):
  File "/home/warproxxx/Desktop/Projects/CryptoTrader/src/data_utils/twitter_data/twitterscraper/query.py", line 158, in query_tweets_once
    pos is None
  File "/home/warproxxx/Desktop/Projects/CryptoTrader/src/data_utils/twitter_data/twitterscraper/query.py", line 89, in query_single_page
    response = requests.get(url, headers=headers)
  File "/usr/local/lib/python3.7/dist-packages/requests/api.py", line 72, in get
    return request('get', url, params=params, **kwargs)
  File "/usr/local/lib/python3.7/dist-packages/requests/api.py", line 58, in request
    return session.request(method=method, url=url, **kwargs)
  File "/usr/local/lib/python3.7/dist-packages/requests/sessions.py", line 512, in request
    resp = self.send(prep, **send_kwargs)
  File "/usr/local/lib/python3.7/dist-packages/requests/sessions.py", line 622, in send
    r = adapter.send(request, **kwargs)
  File "/usr/local/lib/python3.7/dist-packages/requests/adapters.py", line 445, in send
    timeout=timeout
  File "/usr/local/lib/python3.7/dist-packages/urllib3/connectionpool.py", line 600, in urlopen
    chunked=chunked)
  File "/usr/local/lib/python3.7/dist-packages/urllib3/connectionpool.py", line 343, in _make_request
    self._validate_conn(conn)
  File "/usr/local/lib/python3.7/dist-packages/urllib3/connectionpool.py", line 849, in _validate_conn
    conn.connect()
  File "/usr/local/lib/python3.7/dist-packages/urllib3/connection.py", line 314, in connect
    conn = self._new_conn()
  File "/usr/local/lib/python3.7/dist-packages/urllib3/connection.py", line 171, in _new_conn
    (self._dns_host, self.port), self.timeout, **extra_kw)
  File "/usr/local/lib/python3.7/dist-packages/urllib3/util/connection.py", line 56, in create_connection
    for res in socket.getaddrinfo(host, port, family, socket.SOCK_STREAM):
  File "/usr/lib/python3.7/socket.py", line 748, in getaddrinfo
    for res in _socket.getaddrinfo(host, port, family, type, proto, flags):
KeyboardInterrupt
Got 0 tweets for bitcoin%20OR%20BTC%20since%3A2015-01-30%20until%3A2015-01-31.
