Scraping bitcoin Data
Starting Year: 2015 Ending Year: 2018
Current Starting Date:2015-01-01 Current Ending Date:2015-02-01
31
Querying bitcoin OR BTC since:2015-01-01 until:2015-01-02
Querying bitcoin OR BTC since:2015-01-02 until:2015-01-03
Querying bitcoin OR BTC since:2015-01-03 until:2015-01-04
Querying bitcoin OR BTC since:2015-01-04 until:2015-01-05
Querying bitcoin OR BTC since:2015-01-05 until:2015-01-06
Querying bitcoin OR BTC since:2015-01-06 until:2015-01-07
Querying bitcoin OR BTC since:2015-01-07 until:2015-01-08
Querying bitcoin OR BTC since:2015-01-11 until:2015-01-12
Querying bitcoin OR BTC since:2015-01-12 until:2015-01-13
Querying bitcoin OR BTC since:2015-01-08 until:2015-01-09
Querying bitcoin OR BTC since:2015-01-09 until:2015-01-10
Querying bitcoin OR BTC since:2015-01-10 until:2015-01-11
Querying bitcoin OR BTC since:2015-01-13 until:2015-01-14
Querying bitcoin OR BTC since:2015-01-14 until:2015-01-15
Querying bitcoin OR BTC since:2015-01-16 until:2015-01-17
Querying bitcoin OR BTC since:2015-01-15 until:2015-01-16
Querying bitcoin OR BTC since:2015-01-17 until:2015-01-18
Querying bitcoin OR BTC since:2015-01-18 until:2015-01-19
Querying bitcoin OR BTC since:2015-01-19 until:2015-01-20
Querying bitcoin OR BTC since:2015-01-20 until:2015-01-21
Querying bitcoin OR BTC since:2015-01-21 until:2015-01-22
Querying bitcoin OR BTC since:2015-01-22 until:2015-01-23
Querying bitcoin OR BTC since:2015-01-23 until:2015-01-24
Querying bitcoin OR BTC since:2015-01-24 until:2015-01-25
Querying bitcoin OR BTC since:2015-01-26 until:2015-01-27
Querying bitcoin OR BTC since:2015-01-25 until:2015-01-26
Querying bitcoin OR BTC since:2015-01-27 until:2015-01-28
Querying bitcoin OR BTC since:2015-01-28 until:2015-01-29
Querying bitcoin OR BTC since:2015-01-29 until:2015-01-30
Querying bitcoin OR BTC since:2015-01-31 until:2015-02-01
Querying bitcoin OR BTC since:2015-01-30 until:2015-01-31
An unknown error occurred! Returning tweets gathered so far.
Traceback (most recent call last):
  File "/home/warproxxx/Desktop/Projects/CryptoTrader/src/data_utils/twitter_data/twitterscraper/query.py", line 157, in query_tweets_once
    pos is None
  File "/home/warproxxx/Desktop/Projects/CryptoTrader/src/data_utils/twitter_data/twitterscraper/query.py", line 90, in query_single_page
    response = requests.get(url, proxies=self.proxy, headers=headers)
  File "/usr/local/lib/python3.7/dist-packages/requests/api.py", line 72, in get
    return request('get', url, params=params, **kwargs)
  File "/usr/local/lib/python3.7/dist-packages/requests/api.py", line 58, in request
    return session.request(method=method, url=url, **kwargs)
  File "/usr/local/lib/python3.7/dist-packages/requests/sessions.py", line 512, in request
    resp = self.send(prep, **send_kwargs)
  File "/usr/local/lib/python3.7/dist-packages/requests/sessions.py", line 622, in send
    r = adapter.send(request, **kwargs)
  File "/usr/local/lib/python3.7/dist-packages/requests/adapters.py", line 445, in send
    timeout=timeout
  File "/usr/local/lib/python3.7/dist-packages/urllib3/connectionpool.py", line 594, in urlopen
    self._prepare_proxy(conn)
  File "/usr/local/lib/python3.7/dist-packages/urllib3/connectionpool.py", line 815, in _prepare_proxy
    conn.connect()
  File "/usr/local/lib/python3.7/dist-packages/urllib3/connection.py", line 314, in connect
    conn = self._new_conn()
  File "/usr/local/lib/python3.7/dist-packages/urllib3/connection.py", line 171, in _new_conn
    (self._dns_host, self.port), self.timeout, **extra_kw)
  File "/usr/local/lib/python3.7/dist-packages/urllib3/util/connection.py", line 69, in create_connection
    sock.connect(sa)
KeyboardInterrupt
An unknown error occurred! Returning tweets gathered so far.
Traceback (most recent call last):
  File "/home/warproxxx/Desktop/Projects/CryptoTrader/src/data_utils/twitter_data/twitterscraper/query.py", line 157, in query_tweets_once
    pos is None
  File "/home/warproxxx/Desktop/Projects/CryptoTrader/src/data_utils/twitter_data/twitterscraper/query.py", line 90, in query_single_page
    response = requests.get(url, proxies=self.proxy, headers=headers)
  File "/usr/local/lib/python3.7/dist-packages/requests/api.py", line 72, in get
    return request('get', url, params=params, **kwargs)
  File "/usr/local/lib/python3.7/dist-packages/requests/api.py", line 58, in request
    return session.request(method=method, url=url, **kwargs)
  File "/usr/local/lib/python3.7/dist-packages/requests/sessions.py", line 512, in request
    resp = self.send(prep, **send_kwargs)
  File "/usr/local/lib/python3.7/dist-packages/requests/sessions.py", line 622, in send
    r = adapter.send(request, **kwargs)
  File "/usr/local/lib/python3.7/dist-packages/requests/adapters.py", line 445, in send
    timeout=timeout
  File "/usr/local/lib/python3.7/dist-packages/urllib3/connectionpool.py", line 594, in urlopen
    self._prepare_proxy(conn)
  File "/usr/local/lib/python3.7/dist-packages/urllib3/connectionpool.py", line 815, in _prepare_proxy
    conn.connect()
  File "/usr/local/lib/python3.7/dist-packages/urllib3/connection.py", line 314, in connect
    conn = self._new_conn()
  File "/usr/local/lib/python3.7/dist-packages/urllib3/connection.py", line 171, in _new_conn
    (self._dns_host, self.port), self.timeout, **extra_kw)
  File "/usr/local/lib/python3.7/dist-packages/urllib3/util/connection.py", line 69, in create_connection
    sock.connect(sa)
KeyboardInterrupt
Got 0 tweets for bitcoin%20OR%20BTC%20since%3A2015-01-23%20until%3A2015-01-24.
An unknown error occurred! Returning tweets gathered so far.
Traceback (most recent call last):
  File "/home/warproxxx/Desktop/Projects/CryptoTrader/src/data_utils/twitter_data/twitterscraper/query.py", line 157, in query_tweets_once
    pos is None
  File "/home/warproxxx/Desktop/Projects/CryptoTrader/src/data_utils/twitter_data/twitterscraper/query.py", line 90, in query_single_page
    response = requests.get(url, proxies=self.proxy, headers=headers)
  File "/usr/local/lib/python3.7/dist-packages/requests/api.py", line 72, in get
    return request('get', url, params=params, **kwargs)
  File "/usr/local/lib/python3.7/dist-packages/requests/api.py", line 58, in request
    return session.request(method=method, url=url, **kwargs)
  File "/usr/local/lib/python3.7/dist-packages/requests/sessions.py", line 512, in request
    resp = self.send(prep, **send_kwargs)
  File "/usr/local/lib/python3.7/dist-packages/requests/sessions.py", line 622, in send
    r = adapter.send(request, **kwargs)
  File "/usr/local/lib/python3.7/dist-packages/requests/adapters.py", line 445, in send
    timeout=timeout
  File "/usr/local/lib/python3.7/dist-packages/urllib3/connectionpool.py", line 594, in urlopen
    self._prepare_proxy(conn)
  File "/usr/local/lib/python3.7/dist-packages/urllib3/connectionpool.py", line 815, in _prepare_proxy
    conn.connect()
  File "/usr/local/lib/python3.7/dist-packages/urllib3/connection.py", line 314, in connect
    conn = self._new_conn()
  File "/usr/local/lib/python3.7/dist-packages/urllib3/connection.py", line 171, in _new_conn
    (self._dns_host, self.port), self.timeout, **extra_kw)
  File "/usr/local/lib/python3.7/dist-packages/urllib3/util/connection.py", line 69, in create_connection
    sock.connect(sa)
KeyboardInterrupt
An unknown error occurred! Returning tweets gathered so far.
Traceback (most recent call last):
  File "/home/warproxxx/Desktop/Projects/CryptoTrader/src/data_utils/twitter_data/twitterscraper/query.py", line 157, in query_tweets_once
    pos is None
  File "/home/warproxxx/Desktop/Projects/CryptoTrader/src/data_utils/twitter_data/twitterscraper/query.py", line 90, in query_single_page
    response = requests.get(url, proxies=self.proxy, headers=headers)
  File "/usr/local/lib/python3.7/dist-packages/requests/api.py", line 72, in get
    return request('get', url, params=params, **kwargs)
  File "/usr/local/lib/python3.7/dist-packages/requests/api.py", line 58, in request
    return session.request(method=method, url=url, **kwargs)
  File "/usr/local/lib/python3.7/dist-packages/requests/sessions.py", line 512, in request
    resp = self.send(prep, **send_kwargs)
  File "/usr/local/lib/python3.7/dist-packages/requests/sessions.py", line 622, in send
    r = adapter.send(request, **kwargs)
  File "/usr/local/lib/python3.7/dist-packages/requests/adapters.py", line 445, in send
    timeout=timeout
  File "/usr/local/lib/python3.7/dist-packages/urllib3/connectionpool.py", line 594, in urlopen
    self._prepare_proxy(conn)
  File "/usr/local/lib/python3.7/dist-packages/urllib3/connectionpool.py", line 815, in _prepare_proxy
    conn.connect()
  File "/usr/local/lib/python3.7/dist-packages/urllib3/connection.py", line 314, in connect
    conn = self._new_conn()
  File "/usr/local/lib/python3.7/dist-packages/urllib3/connection.py", line 171, in _new_conn
    (self._dns_host, self.port), self.timeout, **extra_kw)
  File "/usr/local/lib/python3.7/dist-packages/urllib3/util/connection.py", line 69, in create_connection
    sock.connect(sa)
KeyboardInterrupt
Got 0 tweets for bitcoin%20OR%20BTC%20since%3A2015-01-02%20until%3A2015-01-03.
An unknown error occurred! Returning tweets gathered so far.
Traceback (most recent call last):
  File "/home/warproxxx/Desktop/Projects/CryptoTrader/src/data_utils/twitter_data/twitterscraper/query.py", line 157, in query_tweets_once
    pos is None
  File "/home/warproxxx/Desktop/Projects/CryptoTrader/src/data_utils/twitter_data/twitterscraper/query.py", line 90, in query_single_page
    response = requests.get(url, proxies=self.proxy, headers=headers)
  File "/usr/local/lib/python3.7/dist-packages/requests/api.py", line 72, in get
    return request('get', url, params=params, **kwargs)
  File "/usr/local/lib/python3.7/dist-packages/requests/api.py", line 58, in request
    return session.request(method=method, url=url, **kwargs)
  File "/usr/local/lib/python3.7/dist-packages/requests/sessions.py", line 512, in request
    resp = self.send(prep, **send_kwargs)
  File "/usr/local/lib/python3.7/dist-packages/requests/sessions.py", line 622, in send
    r = adapter.send(request, **kwargs)
  File "/usr/local/lib/python3.7/dist-packages/requests/adapters.py", line 445, in send
    timeout=timeout
  File "/usr/local/lib/python3.7/dist-packages/urllib3/connectionpool.py", line 594, in urlopen
    self._prepare_proxy(conn)
  File "/usr/local/lib/python3.7/dist-packages/urllib3/connectionpool.py", line 815, in _prepare_proxy
    conn.connect()
  File "/usr/local/lib/python3.7/dist-packages/urllib3/connection.py", line 314, in connect
    conn = self._new_conn()
  File "/usr/local/lib/python3.7/dist-packages/urllib3/connection.py", line 171, in _new_conn
    (self._dns_host, self.port), self.timeout, **extra_kw)
  File "/usr/local/lib/python3.7/dist-packages/urllib3/util/connection.py", line 69, in create_connection
    sock.connect(sa)
KeyboardInterrupt
Got 0 tweets for bitcoin%20OR%20BTC%20since%3A2015-01-11%20until%3A2015-01-12.
An unknown error occurred! Returning tweets gathered so far.
Traceback (most recent call last):
  File "/home/warproxxx/Desktop/Projects/CryptoTrader/src/data_utils/twitter_data/twitterscraper/query.py", line 157, in query_tweets_once
    pos is None
  File "/home/warproxxx/Desktop/Projects/CryptoTrader/src/data_utils/twitter_data/twitterscraper/query.py", line 90, in query_single_page
    response = requests.get(url, proxies=self.proxy, headers=headers)
  File "/usr/local/lib/python3.7/dist-packages/requests/api.py", line 72, in get
    return request('get', url, params=params, **kwargs)
  File "/usr/local/lib/python3.7/dist-packages/requests/api.py", line 58, in request
    return session.request(method=method, url=url, **kwargs)
  File "/usr/local/lib/python3.7/dist-packages/requests/sessions.py", line 512, in request
    resp = self.send(prep, **send_kwargs)
  File "/usr/local/lib/python3.7/dist-packages/requests/sessions.py", line 622, in send
    r = adapter.send(request, **kwargs)
  File "/usr/local/lib/python3.7/dist-packages/requests/adapters.py", line 445, in send
    timeout=timeout
  File "/usr/local/lib/python3.7/dist-packages/urllib3/connectionpool.py", line 594, in urlopen
    self._prepare_proxy(conn)
  File "/usr/local/lib/python3.7/dist-packages/urllib3/connectionpool.py", line 815, in _prepare_proxy
    conn.connect()
  File "/usr/local/lib/python3.7/dist-packages/urllib3/connection.py", line 314, in connect
    conn = self._new_conn()
  File "/usr/local/lib/python3.7/dist-packages/urllib3/connection.py", line 171, in _new_conn
    (self._dns_host, self.port), self.timeout, **extra_kw)
  File "/usr/local/lib/python3.7/dist-packages/urllib3/util/connection.py", line 69, in create_connection
    sock.connect(sa)
KeyboardInterrupt
Got 0 tweets for bitcoin%20OR%20BTC%20since%3A2015-01-04%20until%3A2015-01-05.
An unknown error occurred! Returning tweets gathered so far.
Traceback (most recent call last):
  File "/home/warproxxx/Desktop/Projects/CryptoTrader/src/data_utils/twitter_data/twitterscraper/query.py", line 157, in query_tweets_once
    pos is None
  File "/home/warproxxx/Desktop/Projects/CryptoTrader/src/data_utils/twitter_data/twitterscraper/query.py", line 90, in query_single_page
    response = requests.get(url, proxies=self.proxy, headers=headers)
  File "/usr/local/lib/python3.7/dist-packages/requests/api.py", line 72, in get
    return request('get', url, params=params, **kwargs)
  File "/usr/local/lib/python3.7/dist-packages/requests/api.py", line 58, in request
    return session.request(method=method, url=url, **kwargs)
  File "/usr/local/lib/python3.7/dist-packages/requests/sessions.py", line 512, in request
    resp = self.send(prep, **send_kwargs)
  File "/usr/local/lib/python3.7/dist-packages/requests/sessions.py", line 622, in send
    r = adapter.send(request, **kwargs)
  File "/usr/local/lib/python3.7/dist-packages/requests/adapters.py", line 445, in send
    timeout=timeout
  File "/usr/local/lib/python3.7/dist-packages/urllib3/connectionpool.py", line 594, in urlopen
    self._prepare_proxy(conn)
  File "/usr/local/lib/python3.7/dist-packages/urllib3/connectionpool.py", line 815, in _prepare_proxy
    conn.connect()
  File "/usr/local/lib/python3.7/dist-packages/urllib3/connection.py", line 314, in connect
    conn = self._new_conn()
  File "/usr/local/lib/python3.7/dist-packages/urllib3/connection.py", line 171, in _new_conn
    (self._dns_host, self.port), self.timeout, **extra_kw)
  File "/usr/local/lib/python3.7/dist-packages/urllib3/util/connection.py", line 69, in create_connection
    sock.connect(sa)
KeyboardInterrupt
An unknown error occurred! Returning tweets gathered so far.
Traceback (most recent call last):
  File "/home/warproxxx/Desktop/Projects/CryptoTrader/src/data_utils/twitter_data/twitterscraper/query.py", line 157, in query_tweets_once
    pos is None
  File "/home/warproxxx/Desktop/Projects/CryptoTrader/src/data_utils/twitter_data/twitterscraper/query.py", line 90, in query_single_page
    response = requests.get(url, proxies=self.proxy, headers=headers)
  File "/usr/local/lib/python3.7/dist-packages/requests/api.py", line 72, in get
    return request('get', url, params=params, **kwargs)
  File "/usr/local/lib/python3.7/dist-packages/requests/api.py", line 58, in request
    return session.request(method=method, url=url, **kwargs)
  File "/usr/local/lib/python3.7/dist-packages/requests/sessions.py", line 512, in request
    resp = self.send(prep, **send_kwargs)
  File "/usr/local/lib/python3.7/dist-packages/requests/sessions.py", line 622, in send
    r = adapter.send(request, **kwargs)
  File "/usr/local/lib/python3.7/dist-packages/requests/adapters.py", line 445, in send
    timeout=timeout
  File "/usr/local/lib/python3.7/dist-packages/urllib3/connectionpool.py", line 594, in urlopen
    self._prepare_proxy(conn)
  File "/usr/local/lib/python3.7/dist-packages/urllib3/connectionpool.py", line 815, in _prepare_proxy
    conn.connect()
  File "/usr/local/lib/python3.7/dist-packages/urllib3/connection.py", line 314, in connect
    conn = self._new_conn()
  File "/usr/local/lib/python3.7/dist-packages/urllib3/connection.py", line 171, in _new_conn
    (self._dns_host, self.port), self.timeout, **extra_kw)
  File "/usr/local/lib/python3.7/dist-packages/urllib3/util/connection.py", line 69, in create_connection
    sock.connect(sa)
KeyboardInterrupt
Got 0 tweets for bitcoin%20OR%20BTC%20since%3A2015-01-05%20until%3A2015-01-06.
Got 0 tweets for bitcoin%20OR%20BTC%20since%3A2015-01-31%20until%3A2015-02-01.
Got 0 tweets for bitcoin%20OR%20BTC%20since%3A2015-01-29%20until%3A2015-01-30.
An unknown error occurred! Returning tweets gathered so far.
Traceback (most recent call last):
  File "/home/warproxxx/Desktop/Projects/CryptoTrader/src/data_utils/twitter_data/twitterscraper/query.py", line 157, in query_tweets_once
    pos is None
  File "/home/warproxxx/Desktop/Projects/CryptoTrader/src/data_utils/twitter_data/twitterscraper/query.py", line 90, in query_single_page
    response = requests.get(url, proxies=self.proxy, headers=headers)
  File "/usr/local/lib/python3.7/dist-packages/requests/api.py", line 72, in get
    return request('get', url, params=params, **kwargs)
  File "/usr/local/lib/python3.7/dist-packages/requests/api.py", line 58, in request
    return session.request(method=method, url=url, **kwargs)
  File "/usr/local/lib/python3.7/dist-packages/requests/sessions.py", line 512, in request
    resp = self.send(prep, **send_kwargs)
  File "/usr/local/lib/python3.7/dist-packages/requests/sessions.py", line 622, in send
    r = adapter.send(request, **kwargs)
  File "/usr/local/lib/python3.7/dist-packages/requests/adapters.py", line 445, in send
    timeout=timeout
  File "/usr/local/lib/python3.7/dist-packages/urllib3/connectionpool.py", line 594, in urlopen
    self._prepare_proxy(conn)
  File "/usr/local/lib/python3.7/dist-packages/urllib3/connectionpool.py", line 815, in _prepare_proxy
    conn.connect()
  File "/usr/local/lib/python3.7/dist-packages/urllib3/connection.py", line 314, in connect
    conn = self._new_conn()
  File "/usr/local/lib/python3.7/dist-packages/urllib3/connection.py", line 171, in _new_conn
    (self._dns_host, self.port), self.timeout, **extra_kw)
  File "/usr/local/lib/python3.7/dist-packages/urllib3/util/connection.py", line 69, in create_connection
    sock.connect(sa)
KeyboardInterrupt
Got 0 tweets for bitcoin%20OR%20BTC%20since%3A2015-01-25%20until%3A2015-01-26.
An unknown error occurred! Returning tweets gathered so far.
Traceback (most recent call last):
  File "/home/warproxxx/Desktop/Projects/CryptoTrader/src/data_utils/twitter_data/twitterscraper/query.py", line 157, in query_tweets_once
    pos is None
  File "/home/warproxxx/Desktop/Projects/CryptoTrader/src/data_utils/twitter_data/twitterscraper/query.py", line 90, in query_single_page
    response = requests.get(url, proxies=self.proxy, headers=headers)
  File "/usr/local/lib/python3.7/dist-packages/requests/api.py", line 72, in get
    return request('get', url, params=params, **kwargs)
  File "/usr/local/lib/python3.7/dist-packages/requests/api.py", line 58, in request
    return session.request(method=method, url=url, **kwargs)
  File "/usr/local/lib/python3.7/dist-packages/requests/sessions.py", line 512, in request
    resp = self.send(prep, **send_kwargs)
  File "/usr/local/lib/python3.7/dist-packages/requests/sessions.py", line 622, in send
    r = adapter.send(request, **kwargs)
  File "/usr/local/lib/python3.7/dist-packages/requests/adapters.py", line 445, in send
    timeout=timeout
  File "/usr/local/lib/python3.7/dist-packages/urllib3/connectionpool.py", line 594, in urlopen
    self._prepare_proxy(conn)
  File "/usr/local/lib/python3.7/dist-packages/urllib3/connectionpool.py", line 815, in _prepare_proxy
    conn.connect()
  File "/usr/local/lib/python3.7/dist-packages/urllib3/connection.py", line 314, in connect
    conn = self._new_conn()
  File "/usr/local/lib/python3.7/dist-packages/urllib3/connection.py", line 171, in _new_conn
    (self._dns_host, self.port), self.timeout, **extra_kw)
  File "/usr/local/lib/python3.7/dist-packages/urllib3/util/connection.py", line 69, in create_connection
    sock.connect(sa)
KeyboardInterrupt
An unknown error occurred! Returning tweets gathered so far.
Traceback (most recent call last):
  File "/home/warproxxx/Desktop/Projects/CryptoTrader/src/data_utils/twitter_data/twitterscraper/query.py", line 157, in query_tweets_once
    pos is None
  File "/home/warproxxx/Desktop/Projects/CryptoTrader/src/data_utils/twitter_data/twitterscraper/query.py", line 90, in query_single_page
    response = requests.get(url, proxies=self.proxy, headers=headers)
  File "/usr/local/lib/python3.7/dist-packages/requests/api.py", line 72, in get
    return request('get', url, params=params, **kwargs)
  File "/usr/local/lib/python3.7/dist-packages/requests/api.py", line 58, in request
    return session.request(method=method, url=url, **kwargs)
  File "/usr/local/lib/python3.7/dist-packages/requests/sessions.py", line 512, in request
    resp = self.send(prep, **send_kwargs)
  File "/usr/local/lib/python3.7/dist-packages/requests/sessions.py", line 622, in send
    r = adapter.send(request, **kwargs)
  File "/usr/local/lib/python3.7/dist-packages/requests/adapters.py", line 445, in send
    timeout=timeout
  File "/usr/local/lib/python3.7/dist-packages/urllib3/connectionpool.py", line 594, in urlopen
    self._prepare_proxy(conn)
  File "/usr/local/lib/python3.7/dist-packages/urllib3/connectionpool.py", line 815, in _prepare_proxy
    conn.connect()
  File "/usr/local/lib/python3.7/dist-packages/urllib3/connection.py", line 314, in connect
    conn = self._new_conn()
  File "/usr/local/lib/python3.7/dist-packages/urllib3/connection.py", line 171, in _new_conn
    (self._dns_host, self.port), self.timeout, **extra_kw)
  File "/usr/local/lib/python3.7/dist-packages/urllib3/util/connection.py", line 69, in create_connection
    sock.connect(sa)
KeyboardInterrupt
Got 0 tweets for bitcoin%20OR%20BTC%20since%3A2015-01-15%20until%3A2015-01-16.
An unknown error occurred! Returning tweets gathered so far.
Traceback (most recent call last):
  File "/home/warproxxx/Desktop/Projects/CryptoTrader/src/data_utils/twitter_data/twitterscraper/query.py", line 157, in query_tweets_once
    pos is None
  File "/home/warproxxx/Desktop/Projects/CryptoTrader/src/data_utils/twitter_data/twitterscraper/query.py", line 90, in query_single_page
    response = requests.get(url, proxies=self.proxy, headers=headers)
  File "/usr/local/lib/python3.7/dist-packages/requests/api.py", line 72, in get
    return request('get', url, params=params, **kwargs)
  File "/usr/local/lib/python3.7/dist-packages/requests/api.py", line 58, in request
    return session.request(method=method, url=url, **kwargs)
  File "/usr/local/lib/python3.7/dist-packages/requests/sessions.py", line 512, in request
    resp = self.send(prep, **send_kwargs)
  File "/usr/local/lib/python3.7/dist-packages/requests/sessions.py", line 622, in send
    r = adapter.send(request, **kwargs)
  File "/usr/local/lib/python3.7/dist-packages/requests/adapters.py", line 445, in send
    timeout=timeout
  File "/usr/local/lib/python3.7/dist-packages/urllib3/connectionpool.py", line 594, in urlopen
    self._prepare_proxy(conn)
  File "/usr/local/lib/python3.7/dist-packages/urllib3/connectionpool.py", line 815, in _prepare_proxy
    conn.connect()
  File "/usr/local/lib/python3.7/dist-packages/urllib3/connection.py", line 314, in connect
    conn = self._new_conn()
  File "/usr/local/lib/python3.7/dist-packages/urllib3/connection.py", line 171, in _new_conn
    (self._dns_host, self.port), self.timeout, **extra_kw)
  File "/usr/local/lib/python3.7/dist-packages/urllib3/util/connection.py", line 69, in create_connection
    sock.connect(sa)
KeyboardInterrupt
An unknown error occurred! Returning tweets gathered so far.
Traceback (most recent call last):
  File "/home/warproxxx/Desktop/Projects/CryptoTrader/src/data_utils/twitter_data/twitterscraper/query.py", line 157, in query_tweets_once
    pos is None
  File "/home/warproxxx/Desktop/Projects/CryptoTrader/src/data_utils/twitter_data/twitterscraper/query.py", line 90, in query_single_page
    response = requests.get(url, proxies=self.proxy, headers=headers)
  File "/usr/local/lib/python3.7/dist-packages/requests/api.py", line 72, in get
    return request('get', url, params=params, **kwargs)
  File "/usr/local/lib/python3.7/dist-packages/requests/api.py", line 58, in request
    return session.request(method=method, url=url, **kwargs)
  File "/usr/local/lib/python3.7/dist-packages/requests/sessions.py", line 512, in request
    resp = self.send(prep, **send_kwargs)
  File "/usr/local/lib/python3.7/dist-packages/requests/sessions.py", line 622, in send
    r = adapter.send(request, **kwargs)
  File "/usr/local/lib/python3.7/dist-packages/requests/adapters.py", line 445, in send
    timeout=timeout
  File "/usr/local/lib/python3.7/dist-packages/urllib3/connectionpool.py", line 594, in urlopen
    self._prepare_proxy(conn)
  File "/usr/local/lib/python3.7/dist-packages/urllib3/connectionpool.py", line 815, in _prepare_proxy
    conn.connect()
  File "/usr/local/lib/python3.7/dist-packages/urllib3/connection.py", line 314, in connect
    conn = self._new_conn()
  File "/usr/local/lib/python3.7/dist-packages/urllib3/connection.py", line 171, in _new_conn
    (self._dns_host, self.port), self.timeout, **extra_kw)
  File "/usr/local/lib/python3.7/dist-packages/urllib3/util/connection.py", line 69, in create_connection
    sock.connect(sa)
KeyboardInterrupt
Got 0 tweets for bitcoin%20OR%20BTC%20since%3A2015-01-12%20until%3A2015-01-13.
An unknown error occurred! Returning tweets gathered so far.
Traceback (most recent call last):
  File "/home/warproxxx/Desktop/Projects/CryptoTrader/src/data_utils/twitter_data/twitterscraper/query.py", line 157, in query_tweets_once
    pos is None
  File "/home/warproxxx/Desktop/Projects/CryptoTrader/src/data_utils/twitter_data/twitterscraper/query.py", line 90, in query_single_page
    response = requests.get(url, proxies=self.proxy, headers=headers)
  File "/usr/local/lib/python3.7/dist-packages/requests/api.py", line 72, in get
    return request('get', url, params=params, **kwargs)
  File "/usr/local/lib/python3.7/dist-packages/requests/api.py", line 58, in request
    return session.request(method=method, url=url, **kwargs)
  File "/usr/local/lib/python3.7/dist-packages/requests/sessions.py", line 512, in request
    resp = self.send(prep, **send_kwargs)
  File "/usr/local/lib/python3.7/dist-packages/requests/sessions.py", line 622, in send
    r = adapter.send(request, **kwargs)
  File "/usr/local/lib/python3.7/dist-packages/requests/adapters.py", line 445, in send
    timeout=timeout
  File "/usr/local/lib/python3.7/dist-packages/urllib3/connectionpool.py", line 594, in urlopen
    self._prepare_proxy(conn)
  File "/usr/local/lib/python3.7/dist-packages/urllib3/connectionpool.py", line 815, in _prepare_proxy
    conn.connect()
  File "/usr/local/lib/python3.7/dist-packages/urllib3/connection.py", line 314, in connect
    conn = self._new_conn()
  File "/usr/local/lib/python3.7/dist-packages/urllib3/connection.py", line 171, in _new_conn
    (self._dns_host, self.port), self.timeout, **extra_kw)
  File "/usr/local/lib/python3.7/dist-packages/urllib3/util/connection.py", line 69, in create_connection
    sock.connect(sa)
KeyboardInterrupt
Got 0 tweets for bitcoin%20OR%20BTC%20since%3A2015-01-28%20until%3A2015-01-29.
An unknown error occurred! Returning tweets gathered so far.
Traceback (most recent call last):
  File "/home/warproxxx/Desktop/Projects/CryptoTrader/src/data_utils/twitter_data/twitterscraper/query.py", line 157, in query_tweets_once
    pos is None
  File "/home/warproxxx/Desktop/Projects/CryptoTrader/src/data_utils/twitter_data/twitterscraper/query.py", line 90, in query_single_page
    response = requests.get(url, proxies=self.proxy, headers=headers)
  File "/usr/local/lib/python3.7/dist-packages/requests/api.py", line 72, in get
    return request('get', url, params=params, **kwargs)
  File "/usr/local/lib/python3.7/dist-packages/requests/api.py", line 58, in request
    return session.request(method=method, url=url, **kwargs)
  File "/usr/local/lib/python3.7/dist-packages/requests/sessions.py", line 512, in request
    resp = self.send(prep, **send_kwargs)
  File "/usr/local/lib/python3.7/dist-packages/requests/sessions.py", line 622, in send
    r = adapter.send(request, **kwargs)
  File "/usr/local/lib/python3.7/dist-packages/requests/adapters.py", line 445, in send
    timeout=timeout
  File "/usr/local/lib/python3.7/dist-packages/urllib3/connectionpool.py", line 594, in urlopen
    self._prepare_proxy(conn)
  File "/usr/local/lib/python3.7/dist-packages/urllib3/connectionpool.py", line 815, in _prepare_proxy
    conn.connect()
  File "/usr/local/lib/python3.7/dist-packages/urllib3/connection.py", line 314, in connect
    conn = self._new_conn()
  File "/usr/local/lib/python3.7/dist-packages/urllib3/connection.py", line 171, in _new_conn
    (self._dns_host, self.port), self.timeout, **extra_kw)
  File "/usr/local/lib/python3.7/dist-packages/urllib3/util/connection.py", line 69, in create_connection
    sock.connect(sa)
KeyboardInterrupt
Got 0 tweets for bitcoin%20OR%20BTC%20since%3A2015-01-13%20until%3A2015-01-14.
An unknown error occurred! Returning tweets gathered so far.
Traceback (most recent call last):
  File "/home/warproxxx/Desktop/Projects/CryptoTrader/src/data_utils/twitter_data/twitterscraper/query.py", line 157, in query_tweets_once
    pos is None
  File "/home/warproxxx/Desktop/Projects/CryptoTrader/src/data_utils/twitter_data/twitterscraper/query.py", line 90, in query_single_page
    response = requests.get(url, proxies=self.proxy, headers=headers)
  File "/usr/local/lib/python3.7/dist-packages/requests/api.py", line 72, in get
    return request('get', url, params=params, **kwargs)
  File "/usr/local/lib/python3.7/dist-packages/requests/api.py", line 58, in request
    return session.request(method=method, url=url, **kwargs)
  File "/usr/local/lib/python3.7/dist-packages/requests/sessions.py", line 512, in request
    resp = self.send(prep, **send_kwargs)
  File "/usr/local/lib/python3.7/dist-packages/requests/sessions.py", line 622, in send
    r = adapter.send(request, **kwargs)
  File "/usr/local/lib/python3.7/dist-packages/requests/adapters.py", line 445, in send
    timeout=timeout
  File "/usr/local/lib/python3.7/dist-packages/urllib3/connectionpool.py", line 594, in urlopen
    self._prepare_proxy(conn)
  File "/usr/local/lib/python3.7/dist-packages/urllib3/connectionpool.py", line 815, in _prepare_proxy
    conn.connect()
  File "/usr/local/lib/python3.7/dist-packages/urllib3/connection.py", line 314, in connect
    conn = self._new_conn()
  File "/usr/local/lib/python3.7/dist-packages/urllib3/connection.py", line 171, in _new_conn
    (self._dns_host, self.port), self.timeout, **extra_kw)
  File "/usr/local/lib/python3.7/dist-packages/urllib3/util/connection.py", line 69, in create_connection
    sock.connect(sa)
KeyboardInterrupt
Got 0 tweets for bitcoin%20OR%20BTC%20since%3A2015-01-22%20until%3A2015-01-23.
Got 0 tweets for bitcoin%20OR%20BTC%20since%3A2015-01-19%20until%3A2015-01-20.
An unknown error occurred! Returning tweets gathered so far.
Traceback (most recent call last):
  File "/home/warproxxx/Desktop/Projects/CryptoTrader/src/data_utils/twitter_data/twitterscraper/query.py", line 157, in query_tweets_once
    pos is None
  File "/home/warproxxx/Desktop/Projects/CryptoTrader/src/data_utils/twitter_data/twitterscraper/query.py", line 90, in query_single_page
    response = requests.get(url, proxies=self.proxy, headers=headers)
  File "/usr/local/lib/python3.7/dist-packages/requests/api.py", line 72, in get
    return request('get', url, params=params, **kwargs)
  File "/usr/local/lib/python3.7/dist-packages/requests/api.py", line 58, in request
    return session.request(method=method, url=url, **kwargs)
  File "/usr/local/lib/python3.7/dist-packages/requests/sessions.py", line 512, in request
    resp = self.send(prep, **send_kwargs)
  File "/usr/local/lib/python3.7/dist-packages/requests/sessions.py", line 622, in send
    r = adapter.send(request, **kwargs)
  File "/usr/local/lib/python3.7/dist-packages/requests/adapters.py", line 445, in send
    timeout=timeout
  File "/usr/local/lib/python3.7/dist-packages/urllib3/connectionpool.py", line 594, in urlopen
    self._prepare_proxy(conn)
  File "/usr/local/lib/python3.7/dist-packages/urllib3/connectionpool.py", line 815, in _prepare_proxy
    conn.connect()
  File "/usr/local/lib/python3.7/dist-packages/urllib3/connection.py", line 314, in connect
    conn = self._new_conn()
  File "/usr/local/lib/python3.7/dist-packages/urllib3/connection.py", line 171, in _new_conn
    (self._dns_host, self.port), self.timeout, **extra_kw)
  File "/usr/local/lib/python3.7/dist-packages/urllib3/util/connection.py", line 69, in create_connection
    sock.connect(sa)
KeyboardInterrupt
An unknown error occurred! Returning tweets gathered so far.
Traceback (most recent call last):
  File "/home/warproxxx/Desktop/Projects/CryptoTrader/src/data_utils/twitter_data/twitterscraper/query.py", line 157, in query_tweets_once
    pos is None
  File "/home/warproxxx/Desktop/Projects/CryptoTrader/src/data_utils/twitter_data/twitterscraper/query.py", line 90, in query_single_page
    response = requests.get(url, proxies=self.proxy, headers=headers)
  File "/usr/local/lib/python3.7/dist-packages/requests/api.py", line 72, in get
    return request('get', url, params=params, **kwargs)
  File "/usr/local/lib/python3.7/dist-packages/requests/api.py", line 58, in request
    return session.request(method=method, url=url, **kwargs)
  File "/usr/local/lib/python3.7/dist-packages/requests/sessions.py", line 512, in request
    resp = self.send(prep, **send_kwargs)
  File "/usr/local/lib/python3.7/dist-packages/requests/sessions.py", line 622, in send
    r = adapter.send(request, **kwargs)
  File "/usr/local/lib/python3.7/dist-packages/requests/adapters.py", line 445, in send
    timeout=timeout
  File "/usr/local/lib/python3.7/dist-packages/urllib3/connectionpool.py", line 594, in urlopen
    self._prepare_proxy(conn)
  File "/usr/local/lib/python3.7/dist-packages/urllib3/connectionpool.py", line 815, in _prepare_proxy
    conn.connect()
  File "/usr/local/lib/python3.7/dist-packages/urllib3/connection.py", line 314, in connect
    conn = self._new_conn()
  File "/usr/local/lib/python3.7/dist-packages/urllib3/connection.py", line 171, in _new_conn
    (self._dns_host, self.port), self.timeout, **extra_kw)
  File "/usr/local/lib/python3.7/dist-packages/urllib3/util/connection.py", line 69, in create_connection
    sock.connect(sa)
KeyboardInterrupt
Got 0 tweets for bitcoin%20OR%20BTC%20since%3A2015-01-06%20until%3A2015-01-07.
Got 0 tweets for bitcoin%20OR%20BTC%20since%3A2015-01-14%20until%3A2015-01-15.
An unknown error occurred! Returning tweets gathered so far.
Traceback (most recent call last):
  File "/home/warproxxx/Desktop/Projects/CryptoTrader/src/data_utils/twitter_data/twitterscraper/query.py", line 157, in query_tweets_once
    pos is None
  File "/home/warproxxx/Desktop/Projects/CryptoTrader/src/data_utils/twitter_data/twitterscraper/query.py", line 90, in query_single_page
    response = requests.get(url, proxies=self.proxy, headers=headers)
  File "/usr/local/lib/python3.7/dist-packages/requests/api.py", line 72, in get
    return request('get', url, params=params, **kwargs)
  File "/usr/local/lib/python3.7/dist-packages/requests/api.py", line 58, in request
    return session.request(method=method, url=url, **kwargs)
  File "/usr/local/lib/python3.7/dist-packages/requests/sessions.py", line 512, in request
    resp = self.send(prep, **send_kwargs)
  File "/usr/local/lib/python3.7/dist-packages/requests/sessions.py", line 622, in send
    r = adapter.send(request, **kwargs)
  File "/usr/local/lib/python3.7/dist-packages/requests/adapters.py", line 445, in send
    timeout=timeout
  File "/usr/local/lib/python3.7/dist-packages/urllib3/connectionpool.py", line 594, in urlopen
    self._prepare_proxy(conn)
  File "/usr/local/lib/python3.7/dist-packages/urllib3/connectionpool.py", line 815, in _prepare_proxy
    conn.connect()
  File "/usr/local/lib/python3.7/dist-packages/urllib3/connection.py", line 314, in connect
    conn = self._new_conn()
  File "/usr/local/lib/python3.7/dist-packages/urllib3/connection.py", line 171, in _new_conn
    (self._dns_host, self.port), self.timeout, **extra_kw)
  File "/usr/local/lib/python3.7/dist-packages/urllib3/util/connection.py", line 69, in create_connection
    sock.connect(sa)
KeyboardInterrupt
An unknown error occurred! Returning tweets gathered so far.
Traceback (most recent call last):
  File "/home/warproxxx/Desktop/Projects/CryptoTrader/src/data_utils/twitter_data/twitterscraper/query.py", line 157, in query_tweets_once
    pos is None
  File "/home/warproxxx/Desktop/Projects/CryptoTrader/src/data_utils/twitter_data/twitterscraper/query.py", line 90, in query_single_page
    response = requests.get(url, proxies=self.proxy, headers=headers)
  File "/usr/local/lib/python3.7/dist-packages/requests/api.py", line 72, in get
    return request('get', url, params=params, **kwargs)
  File "/usr/local/lib/python3.7/dist-packages/requests/api.py", line 58, in request
    return session.request(method=method, url=url, **kwargs)
  File "/usr/local/lib/python3.7/dist-packages/requests/sessions.py", line 512, in request
    resp = self.send(prep, **send_kwargs)
  File "/usr/local/lib/python3.7/dist-packages/requests/sessions.py", line 622, in send
    r = adapter.send(request, **kwargs)
  File "/usr/local/lib/python3.7/dist-packages/requests/adapters.py", line 445, in send
    timeout=timeout
  File "/usr/local/lib/python3.7/dist-packages/urllib3/connectionpool.py", line 594, in urlopen
    self._prepare_proxy(conn)
  File "/usr/local/lib/python3.7/dist-packages/urllib3/connectionpool.py", line 815, in _prepare_proxy
    conn.connect()
  File "/usr/local/lib/python3.7/dist-packages/urllib3/connection.py", line 314, in connect
    conn = self._new_conn()
  File "/usr/local/lib/python3.7/dist-packages/urllib3/connection.py", line 171, in _new_conn
    (self._dns_host, self.port), self.timeout, **extra_kw)
  File "/usr/local/lib/python3.7/dist-packages/urllib3/util/connection.py", line 69, in create_connection
    sock.connect(sa)
KeyboardInterrupt
Got 0 tweets for bitcoin%20OR%20BTC%20since%3A2015-01-27%20until%3A2015-01-28.
An unknown error occurred! Returning tweets gathered so far.
Traceback (most recent call last):
  File "/home/warproxxx/Desktop/Projects/CryptoTrader/src/data_utils/twitter_data/twitterscraper/query.py", line 157, in query_tweets_once
    pos is None
  File "/home/warproxxx/Desktop/Projects/CryptoTrader/src/data_utils/twitter_data/twitterscraper/query.py", line 90, in query_single_page
    response = requests.get(url, proxies=self.proxy, headers=headers)
  File "/usr/local/lib/python3.7/dist-packages/requests/api.py", line 72, in get
    return request('get', url, params=params, **kwargs)
  File "/usr/local/lib/python3.7/dist-packages/requests/api.py", line 58, in request
    return session.request(method=method, url=url, **kwargs)
  File "/usr/local/lib/python3.7/dist-packages/requests/sessions.py", line 512, in request
    resp = self.send(prep, **send_kwargs)
  File "/usr/local/lib/python3.7/dist-packages/requests/sessions.py", line 622, in send
    r = adapter.send(request, **kwargs)
  File "/usr/local/lib/python3.7/dist-packages/requests/adapters.py", line 445, in send
    timeout=timeout
  File "/usr/local/lib/python3.7/dist-packages/urllib3/connectionpool.py", line 594, in urlopen
    self._prepare_proxy(conn)
  File "/usr/local/lib/python3.7/dist-packages/urllib3/connectionpool.py", line 815, in _prepare_proxy
    conn.connect()
  File "/usr/local/lib/python3.7/dist-packages/urllib3/connection.py", line 314, in connect
    conn = self._new_conn()
  File "/usr/local/lib/python3.7/dist-packages/urllib3/connection.py", line 171, in _new_conn
    (self._dns_host, self.port), self.timeout, **extra_kw)
  File "/usr/local/lib/python3.7/dist-packages/urllib3/util/connection.py", line 69, in create_connection
    sock.connect(sa)
KeyboardInterrupt
An unknown error occurred! Returning tweets gathered so far.
Traceback (most recent call last):
  File "/home/warproxxx/Desktop/Projects/CryptoTrader/src/data_utils/twitter_data/twitterscraper/query.py", line 157, in query_tweets_once
    pos is None
  File "/home/warproxxx/Desktop/Projects/CryptoTrader/src/data_utils/twitter_data/twitterscraper/query.py", line 90, in query_single_page
    response = requests.get(url, proxies=self.proxy, headers=headers)
  File "/usr/local/lib/python3.7/dist-packages/requests/api.py", line 72, in get
    return request('get', url, params=params, **kwargs)
  File "/usr/local/lib/python3.7/dist-packages/requests/api.py", line 58, in request
    return session.request(method=method, url=url, **kwargs)
  File "/usr/local/lib/python3.7/dist-packages/requests/sessions.py", line 512, in request
    resp = self.send(prep, **send_kwargs)
  File "/usr/local/lib/python3.7/dist-packages/requests/sessions.py", line 622, in send
    r = adapter.send(request, **kwargs)
  File "/usr/local/lib/python3.7/dist-packages/requests/adapters.py", line 445, in send
    timeout=timeout
  File "/usr/local/lib/python3.7/dist-packages/urllib3/connectionpool.py", line 594, in urlopen
    self._prepare_proxy(conn)
  File "/usr/local/lib/python3.7/dist-packages/urllib3/connectionpool.py", line 815, in _prepare_proxy
    conn.connect()
  File "/usr/local/lib/python3.7/dist-packages/urllib3/connection.py", line 314, in connect
    conn = self._new_conn()
  File "/usr/local/lib/python3.7/dist-packages/urllib3/connection.py", line 171, in _new_conn
    (self._dns_host, self.port), self.timeout, **extra_kw)
  File "/usr/local/lib/python3.7/dist-packages/urllib3/util/connection.py", line 69, in create_connection
    sock.connect(sa)
KeyboardInterrupt
An unknown error occurred! Returning tweets gathered so far.
Traceback (most recent call last):
  File "/home/warproxxx/Desktop/Projects/CryptoTrader/src/data_utils/twitter_data/twitterscraper/query.py", line 157, in query_tweets_once
    pos is None
  File "/home/warproxxx/Desktop/Projects/CryptoTrader/src/data_utils/twitter_data/twitterscraper/query.py", line 90, in query_single_page
    response = requests.get(url, proxies=self.proxy, headers=headers)
  File "/usr/local/lib/python3.7/dist-packages/requests/api.py", line 72, in get
    return request('get', url, params=params, **kwargs)
  File "/usr/local/lib/python3.7/dist-packages/requests/api.py", line 58, in request
    return session.request(method=method, url=url, **kwargs)
  File "/usr/local/lib/python3.7/dist-packages/requests/sessions.py", line 512, in request
    resp = self.send(prep, **send_kwargs)
  File "/usr/local/lib/python3.7/dist-packages/requests/sessions.py", line 622, in send
    r = adapter.send(request, **kwargs)
  File "/usr/local/lib/python3.7/dist-packages/requests/adapters.py", line 445, in send
    timeout=timeout
  File "/usr/local/lib/python3.7/dist-packages/urllib3/connectionpool.py", line 594, in urlopen
    self._prepare_proxy(conn)
  File "/usr/local/lib/python3.7/dist-packages/urllib3/connectionpool.py", line 815, in _prepare_proxy
    conn.connect()
  File "/usr/local/lib/python3.7/dist-packages/urllib3/connection.py", line 314, in connect
    conn = self._new_conn()
  File "/usr/local/lib/python3.7/dist-packages/urllib3/connection.py", line 171, in _new_conn
    (self._dns_host, self.port), self.timeout, **extra_kw)
  File "/usr/local/lib/python3.7/dist-packages/urllib3/util/connection.py", line 69, in create_connection
    sock.connect(sa)
KeyboardInterrupt
Got 0 tweets for bitcoin%20OR%20BTC%20since%3A2015-01-08%20until%3A2015-01-09.
Got 0 tweets for bitcoin%20OR%20BTC%20since%3A2015-01-24%20until%3A2015-01-25.
An unknown error occurred! Returning tweets gathered so far.
Traceback (most recent call last):
  File "/home/warproxxx/Desktop/Projects/CryptoTrader/src/data_utils/twitter_data/twitterscraper/query.py", line 157, in query_tweets_once
    pos is None
  File "/home/warproxxx/Desktop/Projects/CryptoTrader/src/data_utils/twitter_data/twitterscraper/query.py", line 90, in query_single_page
    response = requests.get(url, proxies=self.proxy, headers=headers)
  File "/usr/local/lib/python3.7/dist-packages/requests/api.py", line 72, in get
    return request('get', url, params=params, **kwargs)
  File "/usr/local/lib/python3.7/dist-packages/requests/api.py", line 58, in request
    return session.request(method=method, url=url, **kwargs)
  File "/usr/local/lib/python3.7/dist-packages/requests/sessions.py", line 512, in request
    resp = self.send(prep, **send_kwargs)
  File "/usr/local/lib/python3.7/dist-packages/requests/sessions.py", line 622, in send
    r = adapter.send(request, **kwargs)
  File "/usr/local/lib/python3.7/dist-packages/requests/adapters.py", line 445, in send
    timeout=timeout
  File "/usr/local/lib/python3.7/dist-packages/urllib3/connectionpool.py", line 594, in urlopen
    self._prepare_proxy(conn)
  File "/usr/local/lib/python3.7/dist-packages/urllib3/connectionpool.py", line 815, in _prepare_proxy
    conn.connect()
  File "/usr/local/lib/python3.7/dist-packages/urllib3/connection.py", line 314, in connect
    conn = self._new_conn()
  File "/usr/local/lib/python3.7/dist-packages/urllib3/connection.py", line 171, in _new_conn
    (self._dns_host, self.port), self.timeout, **extra_kw)
  File "/usr/local/lib/python3.7/dist-packages/urllib3/util/connection.py", line 69, in create_connection
    sock.connect(sa)
KeyboardInterrupt
Got 0 tweets for bitcoin%20OR%20BTC%20since%3A2015-01-01%20until%3A2015-01-02.
Got 0 tweets for bitcoin%20OR%20BTC%20since%3A2015-01-18%20until%3A2015-01-19.
Got 0 tweets for bitcoin%20OR%20BTC%20since%3A2015-01-26%20until%3A2015-01-27.
Got 0 tweets for bitcoin%20OR%20BTC%20since%3A2015-01-21%20until%3A2015-01-22.
An unknown error occurred! Returning tweets gathered so far.
Traceback (most recent call last):
  File "/home/warproxxx/Desktop/Projects/CryptoTrader/src/data_utils/twitter_data/twitterscraper/query.py", line 157, in query_tweets_once
    pos is None
  File "/home/warproxxx/Desktop/Projects/CryptoTrader/src/data_utils/twitter_data/twitterscraper/query.py", line 90, in query_single_page
    response = requests.get(url, proxies=self.proxy, headers=headers)
  File "/usr/local/lib/python3.7/dist-packages/requests/api.py", line 72, in get
    return request('get', url, params=params, **kwargs)
  File "/usr/local/lib/python3.7/dist-packages/requests/api.py", line 58, in request
    return session.request(method=method, url=url, **kwargs)
  File "/usr/local/lib/python3.7/dist-packages/requests/sessions.py", line 512, in request
    resp = self.send(prep, **send_kwargs)
  File "/usr/local/lib/python3.7/dist-packages/requests/sessions.py", line 622, in send
    r = adapter.send(request, **kwargs)
  File "/usr/local/lib/python3.7/dist-packages/requests/adapters.py", line 445, in send
    timeout=timeout
  File "/usr/local/lib/python3.7/dist-packages/urllib3/connectionpool.py", line 594, in urlopen
    self._prepare_proxy(conn)
  File "/usr/local/lib/python3.7/dist-packages/urllib3/connectionpool.py", line 815, in _prepare_proxy
    conn.connect()
  File "/usr/local/lib/python3.7/dist-packages/urllib3/connection.py", line 314, in connect
    conn = self._new_conn()
  File "/usr/local/lib/python3.7/dist-packages/urllib3/connection.py", line 171, in _new_conn
    (self._dns_host, self.port), self.timeout, **extra_kw)
  File "/usr/local/lib/python3.7/dist-packages/urllib3/util/connection.py", line 69, in create_connection
    sock.connect(sa)
KeyboardInterrupt
Got 0 tweets for bitcoin%20OR%20BTC%20since%3A2015-01-30%20until%3A2015-01-31.
An unknown error occurred! Returning tweets gathered so far.
Traceback (most recent call last):
  File "/home/warproxxx/Desktop/Projects/CryptoTrader/src/data_utils/twitter_data/twitterscraper/query.py", line 157, in query_tweets_once
    pos is None
  File "/home/warproxxx/Desktop/Projects/CryptoTrader/src/data_utils/twitter_data/twitterscraper/query.py", line 90, in query_single_page
    response = requests.get(url, proxies=self.proxy, headers=headers)
  File "/usr/local/lib/python3.7/dist-packages/requests/api.py", line 72, in get
    return request('get', url, params=params, **kwargs)
  File "/usr/local/lib/python3.7/dist-packages/requests/api.py", line 58, in request
    return session.request(method=method, url=url, **kwargs)
  File "/usr/local/lib/python3.7/dist-packages/requests/sessions.py", line 512, in request
    resp = self.send(prep, **send_kwargs)
  File "/usr/local/lib/python3.7/dist-packages/requests/sessions.py", line 622, in send
    r = adapter.send(request, **kwargs)
  File "/usr/local/lib/python3.7/dist-packages/requests/adapters.py", line 445, in send
    timeout=timeout
  File "/usr/local/lib/python3.7/dist-packages/urllib3/connectionpool.py", line 594, in urlopen
    self._prepare_proxy(conn)
  File "/usr/local/lib/python3.7/dist-packages/urllib3/connectionpool.py", line 815, in _prepare_proxy
    conn.connect()
  File "/usr/local/lib/python3.7/dist-packages/urllib3/connection.py", line 314, in connect
    conn = self._new_conn()
  File "/usr/local/lib/python3.7/dist-packages/urllib3/connection.py", line 171, in _new_conn
    (self._dns_host, self.port), self.timeout, **extra_kw)
  File "/usr/local/lib/python3.7/dist-packages/urllib3/util/connection.py", line 69, in create_connection
    sock.connect(sa)
KeyboardInterrupt
Got 0 tweets for bitcoin%20OR%20BTC%20since%3A2015-01-09%20until%3A2015-01-10.
An unknown error occurred! Returning tweets gathered so far.
Traceback (most recent call last):
  File "/home/warproxxx/Desktop/Projects/CryptoTrader/src/data_utils/twitter_data/twitterscraper/query.py", line 157, in query_tweets_once
    pos is None
  File "/home/warproxxx/Desktop/Projects/CryptoTrader/src/data_utils/twitter_data/twitterscraper/query.py", line 90, in query_single_page
    response = requests.get(url, proxies=self.proxy, headers=headers)
  File "/usr/local/lib/python3.7/dist-packages/requests/api.py", line 72, in get
    return request('get', url, params=params, **kwargs)
  File "/usr/local/lib/python3.7/dist-packages/requests/api.py", line 58, in request
    return session.request(method=method, url=url, **kwargs)
  File "/usr/local/lib/python3.7/dist-packages/requests/sessions.py", line 512, in request
    resp = self.send(prep, **send_kwargs)
  File "/usr/local/lib/python3.7/dist-packages/requests/sessions.py", line 622, in send
    r = adapter.send(request, **kwargs)
  File "/usr/local/lib/python3.7/dist-packages/requests/adapters.py", line 445, in send
    timeout=timeout
  File "/usr/local/lib/python3.7/dist-packages/urllib3/connectionpool.py", line 594, in urlopen
    self._prepare_proxy(conn)
  File "/usr/local/lib/python3.7/dist-packages/urllib3/connectionpool.py", line 815, in _prepare_proxy
    conn.connect()
  File "/usr/local/lib/python3.7/dist-packages/urllib3/connection.py", line 314, in connect
    conn = self._new_conn()
  File "/usr/local/lib/python3.7/dist-packages/urllib3/connection.py", line 171, in _new_conn
    (self._dns_host, self.port), self.timeout, **extra_kw)
  File "/usr/local/lib/python3.7/dist-packages/urllib3/util/connection.py", line 69, in create_connection
    sock.connect(sa)
KeyboardInterrupt
Got 0 tweets for bitcoin%20OR%20BTC%20since%3A2015-01-17%20until%3A2015-01-18.
Got 0 tweets for bitcoin%20OR%20BTC%20since%3A2015-01-16%20until%3A2015-01-17.
An unknown error occurred! Returning tweets gathered so far.
Traceback (most recent call last):
  File "/home/warproxxx/Desktop/Projects/CryptoTrader/src/data_utils/twitter_data/twitterscraper/query.py", line 157, in query_tweets_once
    pos is None
  File "/home/warproxxx/Desktop/Projects/CryptoTrader/src/data_utils/twitter_data/twitterscraper/query.py", line 90, in query_single_page
    response = requests.get(url, proxies=self.proxy, headers=headers)
  File "/usr/local/lib/python3.7/dist-packages/requests/api.py", line 72, in get
    return request('get', url, params=params, **kwargs)
  File "/usr/local/lib/python3.7/dist-packages/requests/api.py", line 58, in request
    return session.request(method=method, url=url, **kwargs)
  File "/usr/local/lib/python3.7/dist-packages/requests/sessions.py", line 512, in request
    resp = self.send(prep, **send_kwargs)
  File "/usr/local/lib/python3.7/dist-packages/requests/sessions.py", line 622, in send
    r = adapter.send(request, **kwargs)
  File "/usr/local/lib/python3.7/dist-packages/requests/adapters.py", line 445, in send
    timeout=timeout
  File "/usr/local/lib/python3.7/dist-packages/urllib3/connectionpool.py", line 594, in urlopen
    self._prepare_proxy(conn)
  File "/usr/local/lib/python3.7/dist-packages/urllib3/connectionpool.py", line 815, in _prepare_proxy
    conn.connect()
  File "/usr/local/lib/python3.7/dist-packages/urllib3/connection.py", line 314, in connect
    conn = self._new_conn()
  File "/usr/local/lib/python3.7/dist-packages/urllib3/connection.py", line 171, in _new_conn
    (self._dns_host, self.port), self.timeout, **extra_kw)
  File "/usr/local/lib/python3.7/dist-packages/urllib3/util/connection.py", line 69, in create_connection
    sock.connect(sa)
KeyboardInterrupt
Got 0 tweets for bitcoin%20OR%20BTC%20since%3A2015-01-20%20until%3A2015-01-21.
An unknown error occurred! Returning tweets gathered so far.
Traceback (most recent call last):
  File "/home/warproxxx/Desktop/Projects/CryptoTrader/src/data_utils/twitter_data/twitterscraper/query.py", line 157, in query_tweets_once
    pos is None
  File "/home/warproxxx/Desktop/Projects/CryptoTrader/src/data_utils/twitter_data/twitterscraper/query.py", line 90, in query_single_page
    response = requests.get(url, proxies=self.proxy, headers=headers)
  File "/usr/local/lib/python3.7/dist-packages/requests/api.py", line 72, in get
    return request('get', url, params=params, **kwargs)
  File "/usr/local/lib/python3.7/dist-packages/requests/api.py", line 58, in request
    return session.request(method=method, url=url, **kwargs)
  File "/usr/local/lib/python3.7/dist-packages/requests/sessions.py", line 512, in request
    resp = self.send(prep, **send_kwargs)
  File "/usr/local/lib/python3.7/dist-packages/requests/sessions.py", line 622, in send
    r = adapter.send(request, **kwargs)
  File "/usr/local/lib/python3.7/dist-packages/requests/adapters.py", line 445, in send
    timeout=timeout
  File "/usr/local/lib/python3.7/dist-packages/urllib3/connectionpool.py", line 594, in urlopen
    self._prepare_proxy(conn)
  File "/usr/local/lib/python3.7/dist-packages/urllib3/connectionpool.py", line 815, in _prepare_proxy
    conn.connect()
  File "/usr/local/lib/python3.7/dist-packages/urllib3/connection.py", line 314, in connect
    conn = self._new_conn()
  File "/usr/local/lib/python3.7/dist-packages/urllib3/connection.py", line 171, in _new_conn
    (self._dns_host, self.port), self.timeout, **extra_kw)
  File "/usr/local/lib/python3.7/dist-packages/urllib3/util/connection.py", line 69, in create_connection
    sock.connect(sa)
KeyboardInterrupt
An unknown error occurred! Returning tweets gathered so far.
Traceback (most recent call last):
  File "/home/warproxxx/Desktop/Projects/CryptoTrader/src/data_utils/twitter_data/twitterscraper/query.py", line 157, in query_tweets_once
    pos is None
  File "/home/warproxxx/Desktop/Projects/CryptoTrader/src/data_utils/twitter_data/twitterscraper/query.py", line 90, in query_single_page
    response = requests.get(url, proxies=self.proxy, headers=headers)
  File "/usr/local/lib/python3.7/dist-packages/requests/api.py", line 72, in get
    return request('get', url, params=params, **kwargs)
  File "/usr/local/lib/python3.7/dist-packages/requests/api.py", line 58, in request
    return session.request(method=method, url=url, **kwargs)
  File "/usr/local/lib/python3.7/dist-packages/requests/sessions.py", line 512, in request
    resp = self.send(prep, **send_kwargs)
  File "/usr/local/lib/python3.7/dist-packages/requests/sessions.py", line 622, in send
    r = adapter.send(request, **kwargs)
  File "/usr/local/lib/python3.7/dist-packages/requests/adapters.py", line 445, in send
    timeout=timeout
  File "/usr/local/lib/python3.7/dist-packages/urllib3/connectionpool.py", line 594, in urlopen
    self._prepare_proxy(conn)
  File "/usr/local/lib/python3.7/dist-packages/urllib3/connectionpool.py", line 815, in _prepare_proxy
    conn.connect()
  File "/usr/local/lib/python3.7/dist-packages/urllib3/connection.py", line 314, in connect
    conn = self._new_conn()
  File "/usr/local/lib/python3.7/dist-packages/urllib3/connection.py", line 171, in _new_conn
    (self._dns_host, self.port), self.timeout, **extra_kw)
  File "/usr/local/lib/python3.7/dist-packages/urllib3/util/connection.py", line 69, in create_connection
    sock.connect(sa)
KeyboardInterrupt
Got 0 tweets for bitcoin%20OR%20BTC%20since%3A2015-01-03%20until%3A2015-01-04.
Got 0 tweets for bitcoin%20OR%20BTC%20since%3A2015-01-07%20until%3A2015-01-08.
An unknown error occurred! Returning tweets gathered so far.
Traceback (most recent call last):
  File "/home/warproxxx/Desktop/Projects/CryptoTrader/src/data_utils/twitter_data/twitterscraper/query.py", line 157, in query_tweets_once
    pos is None
  File "/home/warproxxx/Desktop/Projects/CryptoTrader/src/data_utils/twitter_data/twitterscraper/query.py", line 90, in query_single_page
    response = requests.get(url, proxies=self.proxy, headers=headers)
  File "/usr/local/lib/python3.7/dist-packages/requests/api.py", line 72, in get
    return request('get', url, params=params, **kwargs)
  File "/usr/local/lib/python3.7/dist-packages/requests/api.py", line 58, in request
    return session.request(method=method, url=url, **kwargs)
  File "/usr/local/lib/python3.7/dist-packages/requests/sessions.py", line 512, in request
    resp = self.send(prep, **send_kwargs)
  File "/usr/local/lib/python3.7/dist-packages/requests/sessions.py", line 622, in send
    r = adapter.send(request, **kwargs)
  File "/usr/local/lib/python3.7/dist-packages/requests/adapters.py", line 445, in send
    timeout=timeout
  File "/usr/local/lib/python3.7/dist-packages/urllib3/connectionpool.py", line 594, in urlopen
    self._prepare_proxy(conn)
  File "/usr/local/lib/python3.7/dist-packages/urllib3/connectionpool.py", line 815, in _prepare_proxy
    conn.connect()
  File "/usr/local/lib/python3.7/dist-packages/urllib3/connection.py", line 314, in connect
    conn = self._new_conn()
  File "/usr/local/lib/python3.7/dist-packages/urllib3/connection.py", line 171, in _new_conn
    (self._dns_host, self.port), self.timeout, **extra_kw)
  File "/usr/local/lib/python3.7/dist-packages/urllib3/util/connection.py", line 69, in create_connection
    sock.connect(sa)
KeyboardInterrupt
Got 0 tweets for bitcoin%20OR%20BTC%20since%3A2015-01-10%20until%3A2015-01-11.
